<mujoco model="mpc_scaling_experiment">
  <compiler angle="radian" meshdir="../../../mujoco_swarm_demo/models/assets" autolimits="true"/>

  <option integrator="Euler" timestep="0.005">
    <flag contact="enable" warmstart="enable"/>
  </option>

  <size njmax="500" nconmax="200"/>

  <statistic center="1.5 0 0.4" extent="5"/>

  <visual>
    <headlight diffuse="0.6 0.6 0.6" ambient="0.3 0.3 0.3" specular="0 0 0"/>
    <rgba haze="0.15 0.25 0.35 1"/>
    <global azimuth="120" elevation="-20"/>
  </visual>

  <asset>
    <!-- Textures -->
    <texture type="skybox" builtin="gradient" rgb1="0.3 0.5 0.7" rgb2="0 0 0" width="512" height="3072"/>
    <texture type="2d" name="groundplane" builtin="checker" mark="edge" rgb1="0.2 0.3 0.4"
             rgb2="0.1 0.2 0.3" markrgb="0.8 0.8 0.8" width="300" height="300"/>
    <material name="groundplane" texture="groundplane" texuniform="true" texrepeat="5 5" reflectance="0.2"/>

    <!-- Robot meshes -->
    <mesh name="waffle_pi_base" file="waffle_pi_base.stl" scale="0.001 0.001 0.001"/>
    <mesh name="left_tire" file="left_tire.stl" scale="0.001 0.001 0.001"/>
    <mesh name="right_tire" file="right_tire.stl" scale="0.001 0.001 0.001"/>
    <mesh name="lds" file="lds.stl" scale="0.001 0.001 0.001"/>
  </asset>

  <default>
    <joint limited="false" armature="0.01" damping="0.1"/>
    <geom condim="4" friction="1 0.005 0.0001" solimp="0.99 0.99 0.001" solref="0.01 1"/>
    <equality solref="0.0002 1" solimp="0.99 0.99 0.0001"/>
  </default>

  <worldbody>
    <light pos="1.5 0 3" dir="0 0 -1" directional="true"/>
    <geom name="floor" size="0 0 0.05" type="plane" material="groundplane"/>

    <!-- Goal marker (visual only) -->
    <geom name="goal_marker" type="box" size="0.05 11.2 0.01"
          pos="3.0 0.0 0.01" rgba="0.3 0.8 0.3 0.3" contype="0" conaffinity="0"/>

    <!-- Robots -->

    <!-- Robot 0 -->
    <body name="robot_0_base" pos="-0.55 -10.08 0.033" euler="0 0 0.0">
      <freejoint name="robot_0_joint"/>
      <geom pos="-0.064 0 0.01" quat="1 0 0 0" type="mesh" rgba="0.4 0.4 0.4 1" mesh="waffle_pi_base"/>
      <geom size="0.015 0.0045 0.01" pos="-0.177 -0.0639992 0.005" quat="0.707388 -0.706825 0 0" type="box"/>
      <geom size="0.015 0.0045 0.01" pos="-0.177 0.0640008 0.005" quat="0.707388 -0.706825 0 0" type="box"/>
      <geom pos="-0.049 0 0.1255" quat="1 0 0 0" type="mesh" rgba="0.3 0.3 0.3 1" mesh="lds"/>
      <geom size="0.0075 0.015 0.0135" pos="0.078 0 0.107" type="box"/>

      <body name="robot_0_wheel_left" pos="0 0.144 0.033" quat="0.707388 -0.706825 0 0">
        <inertial pos="0 0 0" quat="-0.000890159 0.706886 0.000889646 0.707326" mass="0.0284989" diaginertia="2.07126e-05 1.11924e-05 1.11756e-05"/>
        <joint name="robot_0_wheel_left_joint" pos="0 0 0" axis="0 0 1" limited="false" armature="0.01"/>
        <geom quat="0.707388 0.706825 0 0" type="mesh" rgba="0.3 0.3 0.3 1" mesh="left_tire"/>
      </body>

      <body name="robot_0_wheel_right" pos="0 -0.144 0.033" quat="0.707388 -0.706825 0 0">
        <inertial pos="0 0 0" quat="-0.000890159 0.706886 0.000889646 0.707326" mass="0.0284989" diaginertia="2.07126e-05 1.11924e-05 1.11756e-05"/>
        <joint name="robot_0_wheel_right_joint" pos="0 0 0" axis="0 0 1" limited="false" armature="0.01"/>
        <geom quat="0.707388 0.706825 0 0" type="mesh" rgba="0.3 0.3 0.3 1" mesh="right_tire"/>
      </body>
    </body>

    <!-- Robot 1 -->
    <body name="robot_1_base" pos="-0.55 -9.76 0.033" euler="0 0 0.0">
      <freejoint name="robot_1_joint"/>
      <geom pos="-0.064 0 0.01" quat="1 0 0 0" type="mesh" rgba="0.4 0.4 0.4 1" mesh="waffle_pi_base"/>
      <geom size="0.015 0.0045 0.01" pos="-0.177 -0.0639992 0.005" quat="0.707388 -0.706825 0 0" type="box"/>
      <geom size="0.015 0.0045 0.01" pos="-0.177 0.0640008 0.005" quat="0.707388 -0.706825 0 0" type="box"/>
      <geom pos="-0.049 0 0.1255" quat="1 0 0 0" type="mesh" rgba="0.3 0.3 0.3 1" mesh="lds"/>
      <geom size="0.0075 0.015 0.0135" pos="0.078 0 0.107" type="box"/>

      <body name="robot_1_wheel_left" pos="0 0.144 0.033" quat="0.707388 -0.706825 0 0">
        <inertial pos="0 0 0" quat="-0.000890159 0.706886 0.000889646 0.707326" mass="0.0284989" diaginertia="2.07126e-05 1.11924e-05 1.11756e-05"/>
        <joint name="robot_1_wheel_left_joint" pos="0 0 0" axis="0 0 1" limited="false" armature="0.01"/>
        <geom quat="0.707388 0.706825 0 0" type="mesh" rgba="0.3 0.3 0.3 1" mesh="left_tire"/>
      </body>

      <body name="robot_1_wheel_right" pos="0 -0.144 0.033" quat="0.707388 -0.706825 0 0">
        <inertial pos="0 0 0" quat="-0.000890159 0.706886 0.000889646 0.707326" mass="0.0284989" diaginertia="2.07126e-05 1.11924e-05 1.11756e-05"/>
        <joint name="robot_1_wheel_right_joint" pos="0 0 0" axis="0 0 1" limited="false" armature="0.01"/>
        <geom quat="0.707388 0.706825 0 0" type="mesh" rgba="0.3 0.3 0.3 1" mesh="right_tire"/>
      </body>
    </body>

    <!-- Robot 2 -->
    <body name="robot_2_base" pos="-0.55 -9.44 0.033" euler="0 0 0.0">
      <freejoint name="robot_2_joint"/>
      <geom pos="-0.064 0 0.01" quat="1 0 0 0" type="mesh" rgba="0.4 0.4 0.4 1" mesh="waffle_pi_base"/>
      <geom size="0.015 0.0045 0.01" pos="-0.177 -0.0639992 0.005" quat="0.707388 -0.706825 0 0" type="box"/>
      <geom size="0.015 0.0045 0.01" pos="-0.177 0.0640008 0.005" quat="0.707388 -0.706825 0 0" type="box"/>
      <geom pos="-0.049 0 0.1255" quat="1 0 0 0" type="mesh" rgba="0.3 0.3 0.3 1" mesh="lds"/>
      <geom size="0.0075 0.015 0.0135" pos="0.078 0 0.107" type="box"/>

      <body name="robot_2_wheel_left" pos="0 0.144 0.033" quat="0.707388 -0.706825 0 0">
        <inertial pos="0 0 0" quat="-0.000890159 0.706886 0.000889646 0.707326" mass="0.0284989" diaginertia="2.07126e-05 1.11924e-05 1.11756e-05"/>
        <joint name="robot_2_wheel_left_joint" pos="0 0 0" axis="0 0 1" limited="false" armature="0.01"/>
        <geom quat="0.707388 0.706825 0 0" type="mesh" rgba="0.3 0.3 0.3 1" mesh="left_tire"/>
      </body>

      <body name="robot_2_wheel_right" pos="0 -0.144 0.033" quat="0.707388 -0.706825 0 0">
        <inertial pos="0 0 0" quat="-0.000890159 0.706886 0.000889646 0.707326" mass="0.0284989" diaginertia="2.07126e-05 1.11924e-05 1.11756e-05"/>
        <joint name="robot_2_wheel_right_joint" pos="0 0 0" axis="0 0 1" limited="false" armature="0.01"/>
        <geom quat="0.707388 0.706825 0 0" type="mesh" rgba="0.3 0.3 0.3 1" mesh="right_tire"/>
      </body>
    </body>

    <!-- Robot 3 -->
    <body name="robot_3_base" pos="-0.55 -9.120000000000001 0.033" euler="0 0 0.0">
      <freejoint name="robot_3_joint"/>
      <geom pos="-0.064 0 0.01" quat="1 0 0 0" type="mesh" rgba="0.4 0.4 0.4 1" mesh="waffle_pi_base"/>
      <geom size="0.015 0.0045 0.01" pos="-0.177 -0.0639992 0.005" quat="0.707388 -0.706825 0 0" type="box"/>
      <geom size="0.015 0.0045 0.01" pos="-0.177 0.0640008 0.005" quat="0.707388 -0.706825 0 0" type="box"/>
      <geom pos="-0.049 0 0.1255" quat="1 0 0 0" type="mesh" rgba="0.3 0.3 0.3 1" mesh="lds"/>
      <geom size="0.0075 0.015 0.0135" pos="0.078 0 0.107" type="box"/>

      <body name="robot_3_wheel_left" pos="0 0.144 0.033" quat="0.707388 -0.706825 0 0">
        <inertial pos="0 0 0" quat="-0.000890159 0.706886 0.000889646 0.707326" mass="0.0284989" diaginertia="2.07126e-05 1.11924e-05 1.11756e-05"/>
        <joint name="robot_3_wheel_left_joint" pos="0 0 0" axis="0 0 1" limited="false" armature="0.01"/>
        <geom quat="0.707388 0.706825 0 0" type="mesh" rgba="0.3 0.3 0.3 1" mesh="left_tire"/>
      </body>

      <body name="robot_3_wheel_right" pos="0 -0.144 0.033" quat="0.707388 -0.706825 0 0">
        <inertial pos="0 0 0" quat="-0.000890159 0.706886 0.000889646 0.707326" mass="0.0284989" diaginertia="2.07126e-05 1.11924e-05 1.11756e-05"/>
        <joint name="robot_3_wheel_right_joint" pos="0 0 0" axis="0 0 1" limited="false" armature="0.01"/>
        <geom quat="0.707388 0.706825 0 0" type="mesh" rgba="0.3 0.3 0.3 1" mesh="right_tire"/>
      </body>
    </body>

    <!-- Robot 4 -->
    <body name="robot_4_base" pos="-0.55 -8.8 0.033" euler="0 0 0.0">
      <freejoint name="robot_4_joint"/>
      <geom pos="-0.064 0 0.01" quat="1 0 0 0" type="mesh" rgba="0.4 0.4 0.4 1" mesh="waffle_pi_base"/>
      <geom size="0.015 0.0045 0.01" pos="-0.177 -0.0639992 0.005" quat="0.707388 -0.706825 0 0" type="box"/>
      <geom size="0.015 0.0045 0.01" pos="-0.177 0.0640008 0.005" quat="0.707388 -0.706825 0 0" type="box"/>
      <geom pos="-0.049 0 0.1255" quat="1 0 0 0" type="mesh" rgba="0.3 0.3 0.3 1" mesh="lds"/>
      <geom size="0.0075 0.015 0.0135" pos="0.078 0 0.107" type="box"/>

      <body name="robot_4_wheel_left" pos="0 0.144 0.033" quat="0.707388 -0.706825 0 0">
        <inertial pos="0 0 0" quat="-0.000890159 0.706886 0.000889646 0.707326" mass="0.0284989" diaginertia="2.07126e-05 1.11924e-05 1.11756e-05"/>
        <joint name="robot_4_wheel_left_joint" pos="0 0 0" axis="0 0 1" limited="false" armature="0.01"/>
        <geom quat="0.707388 0.706825 0 0" type="mesh" rgba="0.3 0.3 0.3 1" mesh="left_tire"/>
      </body>

      <body name="robot_4_wheel_right" pos="0 -0.144 0.033" quat="0.707388 -0.706825 0 0">
        <inertial pos="0 0 0" quat="-0.000890159 0.706886 0.000889646 0.707326" mass="0.0284989" diaginertia="2.07126e-05 1.11924e-05 1.11756e-05"/>
        <joint name="robot_4_wheel_right_joint" pos="0 0 0" axis="0 0 1" limited="false" armature="0.01"/>
        <geom quat="0.707388 0.706825 0 0" type="mesh" rgba="0.3 0.3 0.3 1" mesh="right_tire"/>
      </body>
    </body>

    <!-- Robot 5 -->
    <body name="robot_5_base" pos="-0.55 -8.48 0.033" euler="0 0 0.0">
      <freejoint name="robot_5_joint"/>
      <geom pos="-0.064 0 0.01" quat="1 0 0 0" type="mesh" rgba="0.4 0.4 0.4 1" mesh="waffle_pi_base"/>
      <geom size="0.015 0.0045 0.01" pos="-0.177 -0.0639992 0.005" quat="0.707388 -0.706825 0 0" type="box"/>
      <geom size="0.015 0.0045 0.01" pos="-0.177 0.0640008 0.005" quat="0.707388 -0.706825 0 0" type="box"/>
      <geom pos="-0.049 0 0.1255" quat="1 0 0 0" type="mesh" rgba="0.3 0.3 0.3 1" mesh="lds"/>
      <geom size="0.0075 0.015 0.0135" pos="0.078 0 0.107" type="box"/>

      <body name="robot_5_wheel_left" pos="0 0.144 0.033" quat="0.707388 -0.706825 0 0">
        <inertial pos="0 0 0" quat="-0.000890159 0.706886 0.000889646 0.707326" mass="0.0284989" diaginertia="2.07126e-05 1.11924e-05 1.11756e-05"/>
        <joint name="robot_5_wheel_left_joint" pos="0 0 0" axis="0 0 1" limited="false" armature="0.01"/>
        <geom quat="0.707388 0.706825 0 0" type="mesh" rgba="0.3 0.3 0.3 1" mesh="left_tire"/>
      </body>

      <body name="robot_5_wheel_right" pos="0 -0.144 0.033" quat="0.707388 -0.706825 0 0">
        <inertial pos="0 0 0" quat="-0.000890159 0.706886 0.000889646 0.707326" mass="0.0284989" diaginertia="2.07126e-05 1.11924e-05 1.11756e-05"/>
        <joint name="robot_5_wheel_right_joint" pos="0 0 0" axis="0 0 1" limited="false" armature="0.01"/>
        <geom quat="0.707388 0.706825 0 0" type="mesh" rgba="0.3 0.3 0.3 1" mesh="right_tire"/>
      </body>
    </body>

    <!-- Robot 6 -->
    <body name="robot_6_base" pos="-0.55 -8.16 0.033" euler="0 0 0.0">
      <freejoint name="robot_6_joint"/>
      <geom pos="-0.064 0 0.01" quat="1 0 0 0" type="mesh" rgba="0.4 0.4 0.4 1" mesh="waffle_pi_base"/>
      <geom size="0.015 0.0045 0.01" pos="-0.177 -0.0639992 0.005" quat="0.707388 -0.706825 0 0" type="box"/>
      <geom size="0.015 0.0045 0.01" pos="-0.177 0.0640008 0.005" quat="0.707388 -0.706825 0 0" type="box"/>
      <geom pos="-0.049 0 0.1255" quat="1 0 0 0" type="mesh" rgba="0.3 0.3 0.3 1" mesh="lds"/>
      <geom size="0.0075 0.015 0.0135" pos="0.078 0 0.107" type="box"/>

      <body name="robot_6_wheel_left" pos="0 0.144 0.033" quat="0.707388 -0.706825 0 0">
        <inertial pos="0 0 0" quat="-0.000890159 0.706886 0.000889646 0.707326" mass="0.0284989" diaginertia="2.07126e-05 1.11924e-05 1.11756e-05"/>
        <joint name="robot_6_wheel_left_joint" pos="0 0 0" axis="0 0 1" limited="false" armature="0.01"/>
        <geom quat="0.707388 0.706825 0 0" type="mesh" rgba="0.3 0.3 0.3 1" mesh="left_tire"/>
      </body>

      <body name="robot_6_wheel_right" pos="0 -0.144 0.033" quat="0.707388 -0.706825 0 0">
        <inertial pos="0 0 0" quat="-0.000890159 0.706886 0.000889646 0.707326" mass="0.0284989" diaginertia="2.07126e-05 1.11924e-05 1.11756e-05"/>
        <joint name="robot_6_wheel_right_joint" pos="0 0 0" axis="0 0 1" limited="false" armature="0.01"/>
        <geom quat="0.707388 0.706825 0 0" type="mesh" rgba="0.3 0.3 0.3 1" mesh="right_tire"/>
      </body>
    </body>

    <!-- Robot 7 -->
    <body name="robot_7_base" pos="-0.55 -7.84 0.033" euler="0 0 0.0">
      <freejoint name="robot_7_joint"/>
      <geom pos="-0.064 0 0.01" quat="1 0 0 0" type="mesh" rgba="0.4 0.4 0.4 1" mesh="waffle_pi_base"/>
      <geom size="0.015 0.0045 0.01" pos="-0.177 -0.0639992 0.005" quat="0.707388 -0.706825 0 0" type="box"/>
      <geom size="0.015 0.0045 0.01" pos="-0.177 0.0640008 0.005" quat="0.707388 -0.706825 0 0" type="box"/>
      <geom pos="-0.049 0 0.1255" quat="1 0 0 0" type="mesh" rgba="0.3 0.3 0.3 1" mesh="lds"/>
      <geom size="0.0075 0.015 0.0135" pos="0.078 0 0.107" type="box"/>

      <body name="robot_7_wheel_left" pos="0 0.144 0.033" quat="0.707388 -0.706825 0 0">
        <inertial pos="0 0 0" quat="-0.000890159 0.706886 0.000889646 0.707326" mass="0.0284989" diaginertia="2.07126e-05 1.11924e-05 1.11756e-05"/>
        <joint name="robot_7_wheel_left_joint" pos="0 0 0" axis="0 0 1" limited="false" armature="0.01"/>
        <geom quat="0.707388 0.706825 0 0" type="mesh" rgba="0.3 0.3 0.3 1" mesh="left_tire"/>
      </body>

      <body name="robot_7_wheel_right" pos="0 -0.144 0.033" quat="0.707388 -0.706825 0 0">
        <inertial pos="0 0 0" quat="-0.000890159 0.706886 0.000889646 0.707326" mass="0.0284989" diaginertia="2.07126e-05 1.11924e-05 1.11756e-05"/>
        <joint name="robot_7_wheel_right_joint" pos="0 0 0" axis="0 0 1" limited="false" armature="0.01"/>
        <geom quat="0.707388 0.706825 0 0" type="mesh" rgba="0.3 0.3 0.3 1" mesh="right_tire"/>
      </body>
    </body>

    <!-- Robot 8 -->
    <body name="robot_8_base" pos="-0.55 -7.5200000000000005 0.033" euler="0 0 0.0">
      <freejoint name="robot_8_joint"/>
      <geom pos="-0.064 0 0.01" quat="1 0 0 0" type="mesh" rgba="0.4 0.4 0.4 1" mesh="waffle_pi_base"/>
      <geom size="0.015 0.0045 0.01" pos="-0.177 -0.0639992 0.005" quat="0.707388 -0.706825 0 0" type="box"/>
      <geom size="0.015 0.0045 0.01" pos="-0.177 0.0640008 0.005" quat="0.707388 -0.706825 0 0" type="box"/>
      <geom pos="-0.049 0 0.1255" quat="1 0 0 0" type="mesh" rgba="0.3 0.3 0.3 1" mesh="lds"/>
      <geom size="0.0075 0.015 0.0135" pos="0.078 0 0.107" type="box"/>

      <body name="robot_8_wheel_left" pos="0 0.144 0.033" quat="0.707388 -0.706825 0 0">
        <inertial pos="0 0 0" quat="-0.000890159 0.706886 0.000889646 0.707326" mass="0.0284989" diaginertia="2.07126e-05 1.11924e-05 1.11756e-05"/>
        <joint name="robot_8_wheel_left_joint" pos="0 0 0" axis="0 0 1" limited="false" armature="0.01"/>
        <geom quat="0.707388 0.706825 0 0" type="mesh" rgba="0.3 0.3 0.3 1" mesh="left_tire"/>
      </body>

      <body name="robot_8_wheel_right" pos="0 -0.144 0.033" quat="0.707388 -0.706825 0 0">
        <inertial pos="0 0 0" quat="-0.000890159 0.706886 0.000889646 0.707326" mass="0.0284989" diaginertia="2.07126e-05 1.11924e-05 1.11756e-05"/>
        <joint name="robot_8_wheel_right_joint" pos="0 0 0" axis="0 0 1" limited="false" armature="0.01"/>
        <geom quat="0.707388 0.706825 0 0" type="mesh" rgba="0.3 0.3 0.3 1" mesh="right_tire"/>
      </body>
    </body>

    <!-- Robot 9 -->
    <body name="robot_9_base" pos="-0.55 -7.2 0.033" euler="0 0 0.0">
      <freejoint name="robot_9_joint"/>
      <geom pos="-0.064 0 0.01" quat="1 0 0 0" type="mesh" rgba="0.4 0.4 0.4 1" mesh="waffle_pi_base"/>
      <geom size="0.015 0.0045 0.01" pos="-0.177 -0.0639992 0.005" quat="0.707388 -0.706825 0 0" type="box"/>
      <geom size="0.015 0.0045 0.01" pos="-0.177 0.0640008 0.005" quat="0.707388 -0.706825 0 0" type="box"/>
      <geom pos="-0.049 0 0.1255" quat="1 0 0 0" type="mesh" rgba="0.3 0.3 0.3 1" mesh="lds"/>
      <geom size="0.0075 0.015 0.0135" pos="0.078 0 0.107" type="box"/>

      <body name="robot_9_wheel_left" pos="0 0.144 0.033" quat="0.707388 -0.706825 0 0">
        <inertial pos="0 0 0" quat="-0.000890159 0.706886 0.000889646 0.707326" mass="0.0284989" diaginertia="2.07126e-05 1.11924e-05 1.11756e-05"/>
        <joint name="robot_9_wheel_left_joint" pos="0 0 0" axis="0 0 1" limited="false" armature="0.01"/>
        <geom quat="0.707388 0.706825 0 0" type="mesh" rgba="0.3 0.3 0.3 1" mesh="left_tire"/>
      </body>

      <body name="robot_9_wheel_right" pos="0 -0.144 0.033" quat="0.707388 -0.706825 0 0">
        <inertial pos="0 0 0" quat="-0.000890159 0.706886 0.000889646 0.707326" mass="0.0284989" diaginertia="2.07126e-05 1.11924e-05 1.11756e-05"/>
        <joint name="robot_9_wheel_right_joint" pos="0 0 0" axis="0 0 1" limited="false" armature="0.01"/>
        <geom quat="0.707388 0.706825 0 0" type="mesh" rgba="0.3 0.3 0.3 1" mesh="right_tire"/>
      </body>
    </body>

    <!-- Robot 10 -->
    <body name="robot_10_base" pos="-0.55 -6.88 0.033" euler="0 0 0.0">
      <freejoint name="robot_10_joint"/>
      <geom pos="-0.064 0 0.01" quat="1 0 0 0" type="mesh" rgba="0.4 0.4 0.4 1" mesh="waffle_pi_base"/>
      <geom size="0.015 0.0045 0.01" pos="-0.177 -0.0639992 0.005" quat="0.707388 -0.706825 0 0" type="box"/>
      <geom size="0.015 0.0045 0.01" pos="-0.177 0.0640008 0.005" quat="0.707388 -0.706825 0 0" type="box"/>
      <geom pos="-0.049 0 0.1255" quat="1 0 0 0" type="mesh" rgba="0.3 0.3 0.3 1" mesh="lds"/>
      <geom size="0.0075 0.015 0.0135" pos="0.078 0 0.107" type="box"/>

      <body name="robot_10_wheel_left" pos="0 0.144 0.033" quat="0.707388 -0.706825 0 0">
        <inertial pos="0 0 0" quat="-0.000890159 0.706886 0.000889646 0.707326" mass="0.0284989" diaginertia="2.07126e-05 1.11924e-05 1.11756e-05"/>
        <joint name="robot_10_wheel_left_joint" pos="0 0 0" axis="0 0 1" limited="false" armature="0.01"/>
        <geom quat="0.707388 0.706825 0 0" type="mesh" rgba="0.3 0.3 0.3 1" mesh="left_tire"/>
      </body>

      <body name="robot_10_wheel_right" pos="0 -0.144 0.033" quat="0.707388 -0.706825 0 0">
        <inertial pos="0 0 0" quat="-0.000890159 0.706886 0.000889646 0.707326" mass="0.0284989" diaginertia="2.07126e-05 1.11924e-05 1.11756e-05"/>
        <joint name="robot_10_wheel_right_joint" pos="0 0 0" axis="0 0 1" limited="false" armature="0.01"/>
        <geom quat="0.707388 0.706825 0 0" type="mesh" rgba="0.3 0.3 0.3 1" mesh="right_tire"/>
      </body>
    </body>

    <!-- Robot 11 -->
    <body name="robot_11_base" pos="-0.55 -6.5600000000000005 0.033" euler="0 0 0.0">
      <freejoint name="robot_11_joint"/>
      <geom pos="-0.064 0 0.01" quat="1 0 0 0" type="mesh" rgba="0.4 0.4 0.4 1" mesh="waffle_pi_base"/>
      <geom size="0.015 0.0045 0.01" pos="-0.177 -0.0639992 0.005" quat="0.707388 -0.706825 0 0" type="box"/>
      <geom size="0.015 0.0045 0.01" pos="-0.177 0.0640008 0.005" quat="0.707388 -0.706825 0 0" type="box"/>
      <geom pos="-0.049 0 0.1255" quat="1 0 0 0" type="mesh" rgba="0.3 0.3 0.3 1" mesh="lds"/>
      <geom size="0.0075 0.015 0.0135" pos="0.078 0 0.107" type="box"/>

      <body name="robot_11_wheel_left" pos="0 0.144 0.033" quat="0.707388 -0.706825 0 0">
        <inertial pos="0 0 0" quat="-0.000890159 0.706886 0.000889646 0.707326" mass="0.0284989" diaginertia="2.07126e-05 1.11924e-05 1.11756e-05"/>
        <joint name="robot_11_wheel_left_joint" pos="0 0 0" axis="0 0 1" limited="false" armature="0.01"/>
        <geom quat="0.707388 0.706825 0 0" type="mesh" rgba="0.3 0.3 0.3 1" mesh="left_tire"/>
      </body>

      <body name="robot_11_wheel_right" pos="0 -0.144 0.033" quat="0.707388 -0.706825 0 0">
        <inertial pos="0 0 0" quat="-0.000890159 0.706886 0.000889646 0.707326" mass="0.0284989" diaginertia="2.07126e-05 1.11924e-05 1.11756e-05"/>
        <joint name="robot_11_wheel_right_joint" pos="0 0 0" axis="0 0 1" limited="false" armature="0.01"/>
        <geom quat="0.707388 0.706825 0 0" type="mesh" rgba="0.3 0.3 0.3 1" mesh="right_tire"/>
      </body>
    </body>

    <!-- Robot 12 -->
    <body name="robot_12_base" pos="-0.55 -6.24 0.033" euler="0 0 0.0">
      <freejoint name="robot_12_joint"/>
      <geom pos="-0.064 0 0.01" quat="1 0 0 0" type="mesh" rgba="0.4 0.4 0.4 1" mesh="waffle_pi_base"/>
      <geom size="0.015 0.0045 0.01" pos="-0.177 -0.0639992 0.005" quat="0.707388 -0.706825 0 0" type="box"/>
      <geom size="0.015 0.0045 0.01" pos="-0.177 0.0640008 0.005" quat="0.707388 -0.706825 0 0" type="box"/>
      <geom pos="-0.049 0 0.1255" quat="1 0 0 0" type="mesh" rgba="0.3 0.3 0.3 1" mesh="lds"/>
      <geom size="0.0075 0.015 0.0135" pos="0.078 0 0.107" type="box"/>

      <body name="robot_12_wheel_left" pos="0 0.144 0.033" quat="0.707388 -0.706825 0 0">
        <inertial pos="0 0 0" quat="-0.000890159 0.706886 0.000889646 0.707326" mass="0.0284989" diaginertia="2.07126e-05 1.11924e-05 1.11756e-05"/>
        <joint name="robot_12_wheel_left_joint" pos="0 0 0" axis="0 0 1" limited="false" armature="0.01"/>
        <geom quat="0.707388 0.706825 0 0" type="mesh" rgba="0.3 0.3 0.3 1" mesh="left_tire"/>
      </body>

      <body name="robot_12_wheel_right" pos="0 -0.144 0.033" quat="0.707388 -0.706825 0 0">
        <inertial pos="0 0 0" quat="-0.000890159 0.706886 0.000889646 0.707326" mass="0.0284989" diaginertia="2.07126e-05 1.11924e-05 1.11756e-05"/>
        <joint name="robot_12_wheel_right_joint" pos="0 0 0" axis="0 0 1" limited="false" armature="0.01"/>
        <geom quat="0.707388 0.706825 0 0" type="mesh" rgba="0.3 0.3 0.3 1" mesh="right_tire"/>
      </body>
    </body>

    <!-- Robot 13 -->
    <body name="robot_13_base" pos="-0.55 -5.92 0.033" euler="0 0 0.0">
      <freejoint name="robot_13_joint"/>
      <geom pos="-0.064 0 0.01" quat="1 0 0 0" type="mesh" rgba="0.4 0.4 0.4 1" mesh="waffle_pi_base"/>
      <geom size="0.015 0.0045 0.01" pos="-0.177 -0.0639992 0.005" quat="0.707388 -0.706825 0 0" type="box"/>
      <geom size="0.015 0.0045 0.01" pos="-0.177 0.0640008 0.005" quat="0.707388 -0.706825 0 0" type="box"/>
      <geom pos="-0.049 0 0.1255" quat="1 0 0 0" type="mesh" rgba="0.3 0.3 0.3 1" mesh="lds"/>
      <geom size="0.0075 0.015 0.0135" pos="0.078 0 0.107" type="box"/>

      <body name="robot_13_wheel_left" pos="0 0.144 0.033" quat="0.707388 -0.706825 0 0">
        <inertial pos="0 0 0" quat="-0.000890159 0.706886 0.000889646 0.707326" mass="0.0284989" diaginertia="2.07126e-05 1.11924e-05 1.11756e-05"/>
        <joint name="robot_13_wheel_left_joint" pos="0 0 0" axis="0 0 1" limited="false" armature="0.01"/>
        <geom quat="0.707388 0.706825 0 0" type="mesh" rgba="0.3 0.3 0.3 1" mesh="left_tire"/>
      </body>

      <body name="robot_13_wheel_right" pos="0 -0.144 0.033" quat="0.707388 -0.706825 0 0">
        <inertial pos="0 0 0" quat="-0.000890159 0.706886 0.000889646 0.707326" mass="0.0284989" diaginertia="2.07126e-05 1.11924e-05 1.11756e-05"/>
        <joint name="robot_13_wheel_right_joint" pos="0 0 0" axis="0 0 1" limited="false" armature="0.01"/>
        <geom quat="0.707388 0.706825 0 0" type="mesh" rgba="0.3 0.3 0.3 1" mesh="right_tire"/>
      </body>
    </body>

    <!-- Robot 14 -->
    <body name="robot_14_base" pos="-0.55 -5.6000000000000005 0.033" euler="0 0 0.0">
      <freejoint name="robot_14_joint"/>
      <geom pos="-0.064 0 0.01" quat="1 0 0 0" type="mesh" rgba="0.4 0.4 0.4 1" mesh="waffle_pi_base"/>
      <geom size="0.015 0.0045 0.01" pos="-0.177 -0.0639992 0.005" quat="0.707388 -0.706825 0 0" type="box"/>
      <geom size="0.015 0.0045 0.01" pos="-0.177 0.0640008 0.005" quat="0.707388 -0.706825 0 0" type="box"/>
      <geom pos="-0.049 0 0.1255" quat="1 0 0 0" type="mesh" rgba="0.3 0.3 0.3 1" mesh="lds"/>
      <geom size="0.0075 0.015 0.0135" pos="0.078 0 0.107" type="box"/>

      <body name="robot_14_wheel_left" pos="0 0.144 0.033" quat="0.707388 -0.706825 0 0">
        <inertial pos="0 0 0" quat="-0.000890159 0.706886 0.000889646 0.707326" mass="0.0284989" diaginertia="2.07126e-05 1.11924e-05 1.11756e-05"/>
        <joint name="robot_14_wheel_left_joint" pos="0 0 0" axis="0 0 1" limited="false" armature="0.01"/>
        <geom quat="0.707388 0.706825 0 0" type="mesh" rgba="0.3 0.3 0.3 1" mesh="left_tire"/>
      </body>

      <body name="robot_14_wheel_right" pos="0 -0.144 0.033" quat="0.707388 -0.706825 0 0">
        <inertial pos="0 0 0" quat="-0.000890159 0.706886 0.000889646 0.707326" mass="0.0284989" diaginertia="2.07126e-05 1.11924e-05 1.11756e-05"/>
        <joint name="robot_14_wheel_right_joint" pos="0 0 0" axis="0 0 1" limited="false" armature="0.01"/>
        <geom quat="0.707388 0.706825 0 0" type="mesh" rgba="0.3 0.3 0.3 1" mesh="right_tire"/>
      </body>
    </body>

    <!-- Robot 15 -->
    <body name="robot_15_base" pos="-0.55 -5.28 0.033" euler="0 0 0.0">
      <freejoint name="robot_15_joint"/>
      <geom pos="-0.064 0 0.01" quat="1 0 0 0" type="mesh" rgba="0.4 0.4 0.4 1" mesh="waffle_pi_base"/>
      <geom size="0.015 0.0045 0.01" pos="-0.177 -0.0639992 0.005" quat="0.707388 -0.706825 0 0" type="box"/>
      <geom size="0.015 0.0045 0.01" pos="-0.177 0.0640008 0.005" quat="0.707388 -0.706825 0 0" type="box"/>
      <geom pos="-0.049 0 0.1255" quat="1 0 0 0" type="mesh" rgba="0.3 0.3 0.3 1" mesh="lds"/>
      <geom size="0.0075 0.015 0.0135" pos="0.078 0 0.107" type="box"/>

      <body name="robot_15_wheel_left" pos="0 0.144 0.033" quat="0.707388 -0.706825 0 0">
        <inertial pos="0 0 0" quat="-0.000890159 0.706886 0.000889646 0.707326" mass="0.0284989" diaginertia="2.07126e-05 1.11924e-05 1.11756e-05"/>
        <joint name="robot_15_wheel_left_joint" pos="0 0 0" axis="0 0 1" limited="false" armature="0.01"/>
        <geom quat="0.707388 0.706825 0 0" type="mesh" rgba="0.3 0.3 0.3 1" mesh="left_tire"/>
      </body>

      <body name="robot_15_wheel_right" pos="0 -0.144 0.033" quat="0.707388 -0.706825 0 0">
        <inertial pos="0 0 0" quat="-0.000890159 0.706886 0.000889646 0.707326" mass="0.0284989" diaginertia="2.07126e-05 1.11924e-05 1.11756e-05"/>
        <joint name="robot_15_wheel_right_joint" pos="0 0 0" axis="0 0 1" limited="false" armature="0.01"/>
        <geom quat="0.707388 0.706825 0 0" type="mesh" rgba="0.3 0.3 0.3 1" mesh="right_tire"/>
      </body>
    </body>

    <!-- Robot 16 -->
    <body name="robot_16_base" pos="-0.55 -4.96 0.033" euler="0 0 0.0">
      <freejoint name="robot_16_joint"/>
      <geom pos="-0.064 0 0.01" quat="1 0 0 0" type="mesh" rgba="0.4 0.4 0.4 1" mesh="waffle_pi_base"/>
      <geom size="0.015 0.0045 0.01" pos="-0.177 -0.0639992 0.005" quat="0.707388 -0.706825 0 0" type="box"/>
      <geom size="0.015 0.0045 0.01" pos="-0.177 0.0640008 0.005" quat="0.707388 -0.706825 0 0" type="box"/>
      <geom pos="-0.049 0 0.1255" quat="1 0 0 0" type="mesh" rgba="0.3 0.3 0.3 1" mesh="lds"/>
      <geom size="0.0075 0.015 0.0135" pos="0.078 0 0.107" type="box"/>

      <body name="robot_16_wheel_left" pos="0 0.144 0.033" quat="0.707388 -0.706825 0 0">
        <inertial pos="0 0 0" quat="-0.000890159 0.706886 0.000889646 0.707326" mass="0.0284989" diaginertia="2.07126e-05 1.11924e-05 1.11756e-05"/>
        <joint name="robot_16_wheel_left_joint" pos="0 0 0" axis="0 0 1" limited="false" armature="0.01"/>
        <geom quat="0.707388 0.706825 0 0" type="mesh" rgba="0.3 0.3 0.3 1" mesh="left_tire"/>
      </body>

      <body name="robot_16_wheel_right" pos="0 -0.144 0.033" quat="0.707388 -0.706825 0 0">
        <inertial pos="0 0 0" quat="-0.000890159 0.706886 0.000889646 0.707326" mass="0.0284989" diaginertia="2.07126e-05 1.11924e-05 1.11756e-05"/>
        <joint name="robot_16_wheel_right_joint" pos="0 0 0" axis="0 0 1" limited="false" armature="0.01"/>
        <geom quat="0.707388 0.706825 0 0" type="mesh" rgba="0.3 0.3 0.3 1" mesh="right_tire"/>
      </body>
    </body>

    <!-- Robot 17 -->
    <body name="robot_17_base" pos="-0.55 -4.640000000000001 0.033" euler="0 0 0.0">
      <freejoint name="robot_17_joint"/>
      <geom pos="-0.064 0 0.01" quat="1 0 0 0" type="mesh" rgba="0.4 0.4 0.4 1" mesh="waffle_pi_base"/>
      <geom size="0.015 0.0045 0.01" pos="-0.177 -0.0639992 0.005" quat="0.707388 -0.706825 0 0" type="box"/>
      <geom size="0.015 0.0045 0.01" pos="-0.177 0.0640008 0.005" quat="0.707388 -0.706825 0 0" type="box"/>
      <geom pos="-0.049 0 0.1255" quat="1 0 0 0" type="mesh" rgba="0.3 0.3 0.3 1" mesh="lds"/>
      <geom size="0.0075 0.015 0.0135" pos="0.078 0 0.107" type="box"/>

      <body name="robot_17_wheel_left" pos="0 0.144 0.033" quat="0.707388 -0.706825 0 0">
        <inertial pos="0 0 0" quat="-0.000890159 0.706886 0.000889646 0.707326" mass="0.0284989" diaginertia="2.07126e-05 1.11924e-05 1.11756e-05"/>
        <joint name="robot_17_wheel_left_joint" pos="0 0 0" axis="0 0 1" limited="false" armature="0.01"/>
        <geom quat="0.707388 0.706825 0 0" type="mesh" rgba="0.3 0.3 0.3 1" mesh="left_tire"/>
      </body>

      <body name="robot_17_wheel_right" pos="0 -0.144 0.033" quat="0.707388 -0.706825 0 0">
        <inertial pos="0 0 0" quat="-0.000890159 0.706886 0.000889646 0.707326" mass="0.0284989" diaginertia="2.07126e-05 1.11924e-05 1.11756e-05"/>
        <joint name="robot_17_wheel_right_joint" pos="0 0 0" axis="0 0 1" limited="false" armature="0.01"/>
        <geom quat="0.707388 0.706825 0 0" type="mesh" rgba="0.3 0.3 0.3 1" mesh="right_tire"/>
      </body>
    </body>

    <!-- Robot 18 -->
    <body name="robot_18_base" pos="-0.55 -4.32 0.033" euler="0 0 0.0">
      <freejoint name="robot_18_joint"/>
      <geom pos="-0.064 0 0.01" quat="1 0 0 0" type="mesh" rgba="0.4 0.4 0.4 1" mesh="waffle_pi_base"/>
      <geom size="0.015 0.0045 0.01" pos="-0.177 -0.0639992 0.005" quat="0.707388 -0.706825 0 0" type="box"/>
      <geom size="0.015 0.0045 0.01" pos="-0.177 0.0640008 0.005" quat="0.707388 -0.706825 0 0" type="box"/>
      <geom pos="-0.049 0 0.1255" quat="1 0 0 0" type="mesh" rgba="0.3 0.3 0.3 1" mesh="lds"/>
      <geom size="0.0075 0.015 0.0135" pos="0.078 0 0.107" type="box"/>

      <body name="robot_18_wheel_left" pos="0 0.144 0.033" quat="0.707388 -0.706825 0 0">
        <inertial pos="0 0 0" quat="-0.000890159 0.706886 0.000889646 0.707326" mass="0.0284989" diaginertia="2.07126e-05 1.11924e-05 1.11756e-05"/>
        <joint name="robot_18_wheel_left_joint" pos="0 0 0" axis="0 0 1" limited="false" armature="0.01"/>
        <geom quat="0.707388 0.706825 0 0" type="mesh" rgba="0.3 0.3 0.3 1" mesh="left_tire"/>
      </body>

      <body name="robot_18_wheel_right" pos="0 -0.144 0.033" quat="0.707388 -0.706825 0 0">
        <inertial pos="0 0 0" quat="-0.000890159 0.706886 0.000889646 0.707326" mass="0.0284989" diaginertia="2.07126e-05 1.11924e-05 1.11756e-05"/>
        <joint name="robot_18_wheel_right_joint" pos="0 0 0" axis="0 0 1" limited="false" armature="0.01"/>
        <geom quat="0.707388 0.706825 0 0" type="mesh" rgba="0.3 0.3 0.3 1" mesh="right_tire"/>
      </body>
    </body>

    <!-- Robot 19 -->
    <body name="robot_19_base" pos="-0.55 -4.0 0.033" euler="0 0 0.0">
      <freejoint name="robot_19_joint"/>
      <geom pos="-0.064 0 0.01" quat="1 0 0 0" type="mesh" rgba="0.4 0.4 0.4 1" mesh="waffle_pi_base"/>
      <geom size="0.015 0.0045 0.01" pos="-0.177 -0.0639992 0.005" quat="0.707388 -0.706825 0 0" type="box"/>
      <geom size="0.015 0.0045 0.01" pos="-0.177 0.0640008 0.005" quat="0.707388 -0.706825 0 0" type="box"/>
      <geom pos="-0.049 0 0.1255" quat="1 0 0 0" type="mesh" rgba="0.3 0.3 0.3 1" mesh="lds"/>
      <geom size="0.0075 0.015 0.0135" pos="0.078 0 0.107" type="box"/>

      <body name="robot_19_wheel_left" pos="0 0.144 0.033" quat="0.707388 -0.706825 0 0">
        <inertial pos="0 0 0" quat="-0.000890159 0.706886 0.000889646 0.707326" mass="0.0284989" diaginertia="2.07126e-05 1.11924e-05 1.11756e-05"/>
        <joint name="robot_19_wheel_left_joint" pos="0 0 0" axis="0 0 1" limited="false" armature="0.01"/>
        <geom quat="0.707388 0.706825 0 0" type="mesh" rgba="0.3 0.3 0.3 1" mesh="left_tire"/>
      </body>

      <body name="robot_19_wheel_right" pos="0 -0.144 0.033" quat="0.707388 -0.706825 0 0">
        <inertial pos="0 0 0" quat="-0.000890159 0.706886 0.000889646 0.707326" mass="0.0284989" diaginertia="2.07126e-05 1.11924e-05 1.11756e-05"/>
        <joint name="robot_19_wheel_right_joint" pos="0 0 0" axis="0 0 1" limited="false" armature="0.01"/>
        <geom quat="0.707388 0.706825 0 0" type="mesh" rgba="0.3 0.3 0.3 1" mesh="right_tire"/>
      </body>
    </body>

    <!-- Robot 20 -->
    <body name="robot_20_base" pos="-0.55 -3.68 0.033" euler="0 0 0.0">
      <freejoint name="robot_20_joint"/>
      <geom pos="-0.064 0 0.01" quat="1 0 0 0" type="mesh" rgba="0.4 0.4 0.4 1" mesh="waffle_pi_base"/>
      <geom size="0.015 0.0045 0.01" pos="-0.177 -0.0639992 0.005" quat="0.707388 -0.706825 0 0" type="box"/>
      <geom size="0.015 0.0045 0.01" pos="-0.177 0.0640008 0.005" quat="0.707388 -0.706825 0 0" type="box"/>
      <geom pos="-0.049 0 0.1255" quat="1 0 0 0" type="mesh" rgba="0.3 0.3 0.3 1" mesh="lds"/>
      <geom size="0.0075 0.015 0.0135" pos="0.078 0 0.107" type="box"/>

      <body name="robot_20_wheel_left" pos="0 0.144 0.033" quat="0.707388 -0.706825 0 0">
        <inertial pos="0 0 0" quat="-0.000890159 0.706886 0.000889646 0.707326" mass="0.0284989" diaginertia="2.07126e-05 1.11924e-05 1.11756e-05"/>
        <joint name="robot_20_wheel_left_joint" pos="0 0 0" axis="0 0 1" limited="false" armature="0.01"/>
        <geom quat="0.707388 0.706825 0 0" type="mesh" rgba="0.3 0.3 0.3 1" mesh="left_tire"/>
      </body>

      <body name="robot_20_wheel_right" pos="0 -0.144 0.033" quat="0.707388 -0.706825 0 0">
        <inertial pos="0 0 0" quat="-0.000890159 0.706886 0.000889646 0.707326" mass="0.0284989" diaginertia="2.07126e-05 1.11924e-05 1.11756e-05"/>
        <joint name="robot_20_wheel_right_joint" pos="0 0 0" axis="0 0 1" limited="false" armature="0.01"/>
        <geom quat="0.707388 0.706825 0 0" type="mesh" rgba="0.3 0.3 0.3 1" mesh="right_tire"/>
      </body>
    </body>

    <!-- Robot 21 -->
    <body name="robot_21_base" pos="-0.55 -3.3600000000000003 0.033" euler="0 0 0.0">
      <freejoint name="robot_21_joint"/>
      <geom pos="-0.064 0 0.01" quat="1 0 0 0" type="mesh" rgba="0.4 0.4 0.4 1" mesh="waffle_pi_base"/>
      <geom size="0.015 0.0045 0.01" pos="-0.177 -0.0639992 0.005" quat="0.707388 -0.706825 0 0" type="box"/>
      <geom size="0.015 0.0045 0.01" pos="-0.177 0.0640008 0.005" quat="0.707388 -0.706825 0 0" type="box"/>
      <geom pos="-0.049 0 0.1255" quat="1 0 0 0" type="mesh" rgba="0.3 0.3 0.3 1" mesh="lds"/>
      <geom size="0.0075 0.015 0.0135" pos="0.078 0 0.107" type="box"/>

      <body name="robot_21_wheel_left" pos="0 0.144 0.033" quat="0.707388 -0.706825 0 0">
        <inertial pos="0 0 0" quat="-0.000890159 0.706886 0.000889646 0.707326" mass="0.0284989" diaginertia="2.07126e-05 1.11924e-05 1.11756e-05"/>
        <joint name="robot_21_wheel_left_joint" pos="0 0 0" axis="0 0 1" limited="false" armature="0.01"/>
        <geom quat="0.707388 0.706825 0 0" type="mesh" rgba="0.3 0.3 0.3 1" mesh="left_tire"/>
      </body>

      <body name="robot_21_wheel_right" pos="0 -0.144 0.033" quat="0.707388 -0.706825 0 0">
        <inertial pos="0 0 0" quat="-0.000890159 0.706886 0.000889646 0.707326" mass="0.0284989" diaginertia="2.07126e-05 1.11924e-05 1.11756e-05"/>
        <joint name="robot_21_wheel_right_joint" pos="0 0 0" axis="0 0 1" limited="false" armature="0.01"/>
        <geom quat="0.707388 0.706825 0 0" type="mesh" rgba="0.3 0.3 0.3 1" mesh="right_tire"/>
      </body>
    </body>

    <!-- Robot 22 -->
    <body name="robot_22_base" pos="-0.55 -3.0400000000000005 0.033" euler="0 0 0.0">
      <freejoint name="robot_22_joint"/>
      <geom pos="-0.064 0 0.01" quat="1 0 0 0" type="mesh" rgba="0.4 0.4 0.4 1" mesh="waffle_pi_base"/>
      <geom size="0.015 0.0045 0.01" pos="-0.177 -0.0639992 0.005" quat="0.707388 -0.706825 0 0" type="box"/>
      <geom size="0.015 0.0045 0.01" pos="-0.177 0.0640008 0.005" quat="0.707388 -0.706825 0 0" type="box"/>
      <geom pos="-0.049 0 0.1255" quat="1 0 0 0" type="mesh" rgba="0.3 0.3 0.3 1" mesh="lds"/>
      <geom size="0.0075 0.015 0.0135" pos="0.078 0 0.107" type="box"/>

      <body name="robot_22_wheel_left" pos="0 0.144 0.033" quat="0.707388 -0.706825 0 0">
        <inertial pos="0 0 0" quat="-0.000890159 0.706886 0.000889646 0.707326" mass="0.0284989" diaginertia="2.07126e-05 1.11924e-05 1.11756e-05"/>
        <joint name="robot_22_wheel_left_joint" pos="0 0 0" axis="0 0 1" limited="false" armature="0.01"/>
        <geom quat="0.707388 0.706825 0 0" type="mesh" rgba="0.3 0.3 0.3 1" mesh="left_tire"/>
      </body>

      <body name="robot_22_wheel_right" pos="0 -0.144 0.033" quat="0.707388 -0.706825 0 0">
        <inertial pos="0 0 0" quat="-0.000890159 0.706886 0.000889646 0.707326" mass="0.0284989" diaginertia="2.07126e-05 1.11924e-05 1.11756e-05"/>
        <joint name="robot_22_wheel_right_joint" pos="0 0 0" axis="0 0 1" limited="false" armature="0.01"/>
        <geom quat="0.707388 0.706825 0 0" type="mesh" rgba="0.3 0.3 0.3 1" mesh="right_tire"/>
      </body>
    </body>

    <!-- Robot 23 -->
    <body name="robot_23_base" pos="-0.55 -2.7200000000000006 0.033" euler="0 0 0.0">
      <freejoint name="robot_23_joint"/>
      <geom pos="-0.064 0 0.01" quat="1 0 0 0" type="mesh" rgba="0.4 0.4 0.4 1" mesh="waffle_pi_base"/>
      <geom size="0.015 0.0045 0.01" pos="-0.177 -0.0639992 0.005" quat="0.707388 -0.706825 0 0" type="box"/>
      <geom size="0.015 0.0045 0.01" pos="-0.177 0.0640008 0.005" quat="0.707388 -0.706825 0 0" type="box"/>
      <geom pos="-0.049 0 0.1255" quat="1 0 0 0" type="mesh" rgba="0.3 0.3 0.3 1" mesh="lds"/>
      <geom size="0.0075 0.015 0.0135" pos="0.078 0 0.107" type="box"/>

      <body name="robot_23_wheel_left" pos="0 0.144 0.033" quat="0.707388 -0.706825 0 0">
        <inertial pos="0 0 0" quat="-0.000890159 0.706886 0.000889646 0.707326" mass="0.0284989" diaginertia="2.07126e-05 1.11924e-05 1.11756e-05"/>
        <joint name="robot_23_wheel_left_joint" pos="0 0 0" axis="0 0 1" limited="false" armature="0.01"/>
        <geom quat="0.707388 0.706825 0 0" type="mesh" rgba="0.3 0.3 0.3 1" mesh="left_tire"/>
      </body>

      <body name="robot_23_wheel_right" pos="0 -0.144 0.033" quat="0.707388 -0.706825 0 0">
        <inertial pos="0 0 0" quat="-0.000890159 0.706886 0.000889646 0.707326" mass="0.0284989" diaginertia="2.07126e-05 1.11924e-05 1.11756e-05"/>
        <joint name="robot_23_wheel_right_joint" pos="0 0 0" axis="0 0 1" limited="false" armature="0.01"/>
        <geom quat="0.707388 0.706825 0 0" type="mesh" rgba="0.3 0.3 0.3 1" mesh="right_tire"/>
      </body>
    </body>

    <!-- Robot 24 -->
    <body name="robot_24_base" pos="-0.55 -2.4000000000000004 0.033" euler="0 0 0.0">
      <freejoint name="robot_24_joint"/>
      <geom pos="-0.064 0 0.01" quat="1 0 0 0" type="mesh" rgba="0.4 0.4 0.4 1" mesh="waffle_pi_base"/>
      <geom size="0.015 0.0045 0.01" pos="-0.177 -0.0639992 0.005" quat="0.707388 -0.706825 0 0" type="box"/>
      <geom size="0.015 0.0045 0.01" pos="-0.177 0.0640008 0.005" quat="0.707388 -0.706825 0 0" type="box"/>
      <geom pos="-0.049 0 0.1255" quat="1 0 0 0" type="mesh" rgba="0.3 0.3 0.3 1" mesh="lds"/>
      <geom size="0.0075 0.015 0.0135" pos="0.078 0 0.107" type="box"/>

      <body name="robot_24_wheel_left" pos="0 0.144 0.033" quat="0.707388 -0.706825 0 0">
        <inertial pos="0 0 0" quat="-0.000890159 0.706886 0.000889646 0.707326" mass="0.0284989" diaginertia="2.07126e-05 1.11924e-05 1.11756e-05"/>
        <joint name="robot_24_wheel_left_joint" pos="0 0 0" axis="0 0 1" limited="false" armature="0.01"/>
        <geom quat="0.707388 0.706825 0 0" type="mesh" rgba="0.3 0.3 0.3 1" mesh="left_tire"/>
      </body>

      <body name="robot_24_wheel_right" pos="0 -0.144 0.033" quat="0.707388 -0.706825 0 0">
        <inertial pos="0 0 0" quat="-0.000890159 0.706886 0.000889646 0.707326" mass="0.0284989" diaginertia="2.07126e-05 1.11924e-05 1.11756e-05"/>
        <joint name="robot_24_wheel_right_joint" pos="0 0 0" axis="0 0 1" limited="false" armature="0.01"/>
        <geom quat="0.707388 0.706825 0 0" type="mesh" rgba="0.3 0.3 0.3 1" mesh="right_tire"/>
      </body>
    </body>

    <!-- Robot 25 -->
    <body name="robot_25_base" pos="-0.55 -2.0800000000000005 0.033" euler="0 0 0.0">
      <freejoint name="robot_25_joint"/>
      <geom pos="-0.064 0 0.01" quat="1 0 0 0" type="mesh" rgba="0.4 0.4 0.4 1" mesh="waffle_pi_base"/>
      <geom size="0.015 0.0045 0.01" pos="-0.177 -0.0639992 0.005" quat="0.707388 -0.706825 0 0" type="box"/>
      <geom size="0.015 0.0045 0.01" pos="-0.177 0.0640008 0.005" quat="0.707388 -0.706825 0 0" type="box"/>
      <geom pos="-0.049 0 0.1255" quat="1 0 0 0" type="mesh" rgba="0.3 0.3 0.3 1" mesh="lds"/>
      <geom size="0.0075 0.015 0.0135" pos="0.078 0 0.107" type="box"/>

      <body name="robot_25_wheel_left" pos="0 0.144 0.033" quat="0.707388 -0.706825 0 0">
        <inertial pos="0 0 0" quat="-0.000890159 0.706886 0.000889646 0.707326" mass="0.0284989" diaginertia="2.07126e-05 1.11924e-05 1.11756e-05"/>
        <joint name="robot_25_wheel_left_joint" pos="0 0 0" axis="0 0 1" limited="false" armature="0.01"/>
        <geom quat="0.707388 0.706825 0 0" type="mesh" rgba="0.3 0.3 0.3 1" mesh="left_tire"/>
      </body>

      <body name="robot_25_wheel_right" pos="0 -0.144 0.033" quat="0.707388 -0.706825 0 0">
        <inertial pos="0 0 0" quat="-0.000890159 0.706886 0.000889646 0.707326" mass="0.0284989" diaginertia="2.07126e-05 1.11924e-05 1.11756e-05"/>
        <joint name="robot_25_wheel_right_joint" pos="0 0 0" axis="0 0 1" limited="false" armature="0.01"/>
        <geom quat="0.707388 0.706825 0 0" type="mesh" rgba="0.3 0.3 0.3 1" mesh="right_tire"/>
      </body>
    </body>

    <!-- Robot 26 -->
    <body name="robot_26_base" pos="-0.55 -1.7600000000000005 0.033" euler="0 0 0.0">
      <freejoint name="robot_26_joint"/>
      <geom pos="-0.064 0 0.01" quat="1 0 0 0" type="mesh" rgba="0.4 0.4 0.4 1" mesh="waffle_pi_base"/>
      <geom size="0.015 0.0045 0.01" pos="-0.177 -0.0639992 0.005" quat="0.707388 -0.706825 0 0" type="box"/>
      <geom size="0.015 0.0045 0.01" pos="-0.177 0.0640008 0.005" quat="0.707388 -0.706825 0 0" type="box"/>
      <geom pos="-0.049 0 0.1255" quat="1 0 0 0" type="mesh" rgba="0.3 0.3 0.3 1" mesh="lds"/>
      <geom size="0.0075 0.015 0.0135" pos="0.078 0 0.107" type="box"/>

      <body name="robot_26_wheel_left" pos="0 0.144 0.033" quat="0.707388 -0.706825 0 0">
        <inertial pos="0 0 0" quat="-0.000890159 0.706886 0.000889646 0.707326" mass="0.0284989" diaginertia="2.07126e-05 1.11924e-05 1.11756e-05"/>
        <joint name="robot_26_wheel_left_joint" pos="0 0 0" axis="0 0 1" limited="false" armature="0.01"/>
        <geom quat="0.707388 0.706825 0 0" type="mesh" rgba="0.3 0.3 0.3 1" mesh="left_tire"/>
      </body>

      <body name="robot_26_wheel_right" pos="0 -0.144 0.033" quat="0.707388 -0.706825 0 0">
        <inertial pos="0 0 0" quat="-0.000890159 0.706886 0.000889646 0.707326" mass="0.0284989" diaginertia="2.07126e-05 1.11924e-05 1.11756e-05"/>
        <joint name="robot_26_wheel_right_joint" pos="0 0 0" axis="0 0 1" limited="false" armature="0.01"/>
        <geom quat="0.707388 0.706825 0 0" type="mesh" rgba="0.3 0.3 0.3 1" mesh="right_tire"/>
      </body>
    </body>

    <!-- Robot 27 -->
    <body name="robot_27_base" pos="-0.55 -1.4400000000000004 0.033" euler="0 0 0.0">
      <freejoint name="robot_27_joint"/>
      <geom pos="-0.064 0 0.01" quat="1 0 0 0" type="mesh" rgba="0.4 0.4 0.4 1" mesh="waffle_pi_base"/>
      <geom size="0.015 0.0045 0.01" pos="-0.177 -0.0639992 0.005" quat="0.707388 -0.706825 0 0" type="box"/>
      <geom size="0.015 0.0045 0.01" pos="-0.177 0.0640008 0.005" quat="0.707388 -0.706825 0 0" type="box"/>
      <geom pos="-0.049 0 0.1255" quat="1 0 0 0" type="mesh" rgba="0.3 0.3 0.3 1" mesh="lds"/>
      <geom size="0.0075 0.015 0.0135" pos="0.078 0 0.107" type="box"/>

      <body name="robot_27_wheel_left" pos="0 0.144 0.033" quat="0.707388 -0.706825 0 0">
        <inertial pos="0 0 0" quat="-0.000890159 0.706886 0.000889646 0.707326" mass="0.0284989" diaginertia="2.07126e-05 1.11924e-05 1.11756e-05"/>
        <joint name="robot_27_wheel_left_joint" pos="0 0 0" axis="0 0 1" limited="false" armature="0.01"/>
        <geom quat="0.707388 0.706825 0 0" type="mesh" rgba="0.3 0.3 0.3 1" mesh="left_tire"/>
      </body>

      <body name="robot_27_wheel_right" pos="0 -0.144 0.033" quat="0.707388 -0.706825 0 0">
        <inertial pos="0 0 0" quat="-0.000890159 0.706886 0.000889646 0.707326" mass="0.0284989" diaginertia="2.07126e-05 1.11924e-05 1.11756e-05"/>
        <joint name="robot_27_wheel_right_joint" pos="0 0 0" axis="0 0 1" limited="false" armature="0.01"/>
        <geom quat="0.707388 0.706825 0 0" type="mesh" rgba="0.3 0.3 0.3 1" mesh="right_tire"/>
      </body>
    </body>

    <!-- Robot 28 -->
    <body name="robot_28_base" pos="-0.55 -1.1200000000000006 0.033" euler="0 0 0.0">
      <freejoint name="robot_28_joint"/>
      <geom pos="-0.064 0 0.01" quat="1 0 0 0" type="mesh" rgba="0.4 0.4 0.4 1" mesh="waffle_pi_base"/>
      <geom size="0.015 0.0045 0.01" pos="-0.177 -0.0639992 0.005" quat="0.707388 -0.706825 0 0" type="box"/>
      <geom size="0.015 0.0045 0.01" pos="-0.177 0.0640008 0.005" quat="0.707388 -0.706825 0 0" type="box"/>
      <geom pos="-0.049 0 0.1255" quat="1 0 0 0" type="mesh" rgba="0.3 0.3 0.3 1" mesh="lds"/>
      <geom size="0.0075 0.015 0.0135" pos="0.078 0 0.107" type="box"/>

      <body name="robot_28_wheel_left" pos="0 0.144 0.033" quat="0.707388 -0.706825 0 0">
        <inertial pos="0 0 0" quat="-0.000890159 0.706886 0.000889646 0.707326" mass="0.0284989" diaginertia="2.07126e-05 1.11924e-05 1.11756e-05"/>
        <joint name="robot_28_wheel_left_joint" pos="0 0 0" axis="0 0 1" limited="false" armature="0.01"/>
        <geom quat="0.707388 0.706825 0 0" type="mesh" rgba="0.3 0.3 0.3 1" mesh="left_tire"/>
      </body>

      <body name="robot_28_wheel_right" pos="0 -0.144 0.033" quat="0.707388 -0.706825 0 0">
        <inertial pos="0 0 0" quat="-0.000890159 0.706886 0.000889646 0.707326" mass="0.0284989" diaginertia="2.07126e-05 1.11924e-05 1.11756e-05"/>
        <joint name="robot_28_wheel_right_joint" pos="0 0 0" axis="0 0 1" limited="false" armature="0.01"/>
        <geom quat="0.707388 0.706825 0 0" type="mesh" rgba="0.3 0.3 0.3 1" mesh="right_tire"/>
      </body>
    </body>

    <!-- Robot 29 -->
    <body name="robot_29_base" pos="-0.55 -0.8000000000000005 0.033" euler="0 0 0.0">
      <freejoint name="robot_29_joint"/>
      <geom pos="-0.064 0 0.01" quat="1 0 0 0" type="mesh" rgba="0.4 0.4 0.4 1" mesh="waffle_pi_base"/>
      <geom size="0.015 0.0045 0.01" pos="-0.177 -0.0639992 0.005" quat="0.707388 -0.706825 0 0" type="box"/>
      <geom size="0.015 0.0045 0.01" pos="-0.177 0.0640008 0.005" quat="0.707388 -0.706825 0 0" type="box"/>
      <geom pos="-0.049 0 0.1255" quat="1 0 0 0" type="mesh" rgba="0.3 0.3 0.3 1" mesh="lds"/>
      <geom size="0.0075 0.015 0.0135" pos="0.078 0 0.107" type="box"/>

      <body name="robot_29_wheel_left" pos="0 0.144 0.033" quat="0.707388 -0.706825 0 0">
        <inertial pos="0 0 0" quat="-0.000890159 0.706886 0.000889646 0.707326" mass="0.0284989" diaginertia="2.07126e-05 1.11924e-05 1.11756e-05"/>
        <joint name="robot_29_wheel_left_joint" pos="0 0 0" axis="0 0 1" limited="false" armature="0.01"/>
        <geom quat="0.707388 0.706825 0 0" type="mesh" rgba="0.3 0.3 0.3 1" mesh="left_tire"/>
      </body>

      <body name="robot_29_wheel_right" pos="0 -0.144 0.033" quat="0.707388 -0.706825 0 0">
        <inertial pos="0 0 0" quat="-0.000890159 0.706886 0.000889646 0.707326" mass="0.0284989" diaginertia="2.07126e-05 1.11924e-05 1.11756e-05"/>
        <joint name="robot_29_wheel_right_joint" pos="0 0 0" axis="0 0 1" limited="false" armature="0.01"/>
        <geom quat="0.707388 0.706825 0 0" type="mesh" rgba="0.3 0.3 0.3 1" mesh="right_tire"/>
      </body>
    </body>

    <!-- Robot 30 -->
    <body name="robot_30_base" pos="-0.55 -0.48000000000000054 0.033" euler="0 0 0.0">
      <freejoint name="robot_30_joint"/>
      <geom pos="-0.064 0 0.01" quat="1 0 0 0" type="mesh" rgba="0.4 0.4 0.4 1" mesh="waffle_pi_base"/>
      <geom size="0.015 0.0045 0.01" pos="-0.177 -0.0639992 0.005" quat="0.707388 -0.706825 0 0" type="box"/>
      <geom size="0.015 0.0045 0.01" pos="-0.177 0.0640008 0.005" quat="0.707388 -0.706825 0 0" type="box"/>
      <geom pos="-0.049 0 0.1255" quat="1 0 0 0" type="mesh" rgba="0.3 0.3 0.3 1" mesh="lds"/>
      <geom size="0.0075 0.015 0.0135" pos="0.078 0 0.107" type="box"/>

      <body name="robot_30_wheel_left" pos="0 0.144 0.033" quat="0.707388 -0.706825 0 0">
        <inertial pos="0 0 0" quat="-0.000890159 0.706886 0.000889646 0.707326" mass="0.0284989" diaginertia="2.07126e-05 1.11924e-05 1.11756e-05"/>
        <joint name="robot_30_wheel_left_joint" pos="0 0 0" axis="0 0 1" limited="false" armature="0.01"/>
        <geom quat="0.707388 0.706825 0 0" type="mesh" rgba="0.3 0.3 0.3 1" mesh="left_tire"/>
      </body>

      <body name="robot_30_wheel_right" pos="0 -0.144 0.033" quat="0.707388 -0.706825 0 0">
        <inertial pos="0 0 0" quat="-0.000890159 0.706886 0.000889646 0.707326" mass="0.0284989" diaginertia="2.07126e-05 1.11924e-05 1.11756e-05"/>
        <joint name="robot_30_wheel_right_joint" pos="0 0 0" axis="0 0 1" limited="false" armature="0.01"/>
        <geom quat="0.707388 0.706825 0 0" type="mesh" rgba="0.3 0.3 0.3 1" mesh="right_tire"/>
      </body>
    </body>

    <!-- Robot 31 -->
    <body name="robot_31_base" pos="-0.55 -0.16000000000000056 0.033" euler="0 0 0.0">
      <freejoint name="robot_31_joint"/>
      <geom pos="-0.064 0 0.01" quat="1 0 0 0" type="mesh" rgba="0.4 0.4 0.4 1" mesh="waffle_pi_base"/>
      <geom size="0.015 0.0045 0.01" pos="-0.177 -0.0639992 0.005" quat="0.707388 -0.706825 0 0" type="box"/>
      <geom size="0.015 0.0045 0.01" pos="-0.177 0.0640008 0.005" quat="0.707388 -0.706825 0 0" type="box"/>
      <geom pos="-0.049 0 0.1255" quat="1 0 0 0" type="mesh" rgba="0.3 0.3 0.3 1" mesh="lds"/>
      <geom size="0.0075 0.015 0.0135" pos="0.078 0 0.107" type="box"/>

      <body name="robot_31_wheel_left" pos="0 0.144 0.033" quat="0.707388 -0.706825 0 0">
        <inertial pos="0 0 0" quat="-0.000890159 0.706886 0.000889646 0.707326" mass="0.0284989" diaginertia="2.07126e-05 1.11924e-05 1.11756e-05"/>
        <joint name="robot_31_wheel_left_joint" pos="0 0 0" axis="0 0 1" limited="false" armature="0.01"/>
        <geom quat="0.707388 0.706825 0 0" type="mesh" rgba="0.3 0.3 0.3 1" mesh="left_tire"/>
      </body>

      <body name="robot_31_wheel_right" pos="0 -0.144 0.033" quat="0.707388 -0.706825 0 0">
        <inertial pos="0 0 0" quat="-0.000890159 0.706886 0.000889646 0.707326" mass="0.0284989" diaginertia="2.07126e-05 1.11924e-05 1.11756e-05"/>
        <joint name="robot_31_wheel_right_joint" pos="0 0 0" axis="0 0 1" limited="false" armature="0.01"/>
        <geom quat="0.707388 0.706825 0 0" type="mesh" rgba="0.3 0.3 0.3 1" mesh="right_tire"/>
      </body>
    </body>

    <!-- Robot 32 -->
    <body name="robot_32_base" pos="-0.55 0.15999999999999942 0.033" euler="0 0 0.0">
      <freejoint name="robot_32_joint"/>
      <geom pos="-0.064 0 0.01" quat="1 0 0 0" type="mesh" rgba="0.4 0.4 0.4 1" mesh="waffle_pi_base"/>
      <geom size="0.015 0.0045 0.01" pos="-0.177 -0.0639992 0.005" quat="0.707388 -0.706825 0 0" type="box"/>
      <geom size="0.015 0.0045 0.01" pos="-0.177 0.0640008 0.005" quat="0.707388 -0.706825 0 0" type="box"/>
      <geom pos="-0.049 0 0.1255" quat="1 0 0 0" type="mesh" rgba="0.3 0.3 0.3 1" mesh="lds"/>
      <geom size="0.0075 0.015 0.0135" pos="0.078 0 0.107" type="box"/>

      <body name="robot_32_wheel_left" pos="0 0.144 0.033" quat="0.707388 -0.706825 0 0">
        <inertial pos="0 0 0" quat="-0.000890159 0.706886 0.000889646 0.707326" mass="0.0284989" diaginertia="2.07126e-05 1.11924e-05 1.11756e-05"/>
        <joint name="robot_32_wheel_left_joint" pos="0 0 0" axis="0 0 1" limited="false" armature="0.01"/>
        <geom quat="0.707388 0.706825 0 0" type="mesh" rgba="0.3 0.3 0.3 1" mesh="left_tire"/>
      </body>

      <body name="robot_32_wheel_right" pos="0 -0.144 0.033" quat="0.707388 -0.706825 0 0">
        <inertial pos="0 0 0" quat="-0.000890159 0.706886 0.000889646 0.707326" mass="0.0284989" diaginertia="2.07126e-05 1.11924e-05 1.11756e-05"/>
        <joint name="robot_32_wheel_right_joint" pos="0 0 0" axis="0 0 1" limited="false" armature="0.01"/>
        <geom quat="0.707388 0.706825 0 0" type="mesh" rgba="0.3 0.3 0.3 1" mesh="right_tire"/>
      </body>
    </body>

    <!-- Robot 33 -->
    <body name="robot_33_base" pos="-0.55 0.48000000000000054 0.033" euler="0 0 0.0">
      <freejoint name="robot_33_joint"/>
      <geom pos="-0.064 0 0.01" quat="1 0 0 0" type="mesh" rgba="0.4 0.4 0.4 1" mesh="waffle_pi_base"/>
      <geom size="0.015 0.0045 0.01" pos="-0.177 -0.0639992 0.005" quat="0.707388 -0.706825 0 0" type="box"/>
      <geom size="0.015 0.0045 0.01" pos="-0.177 0.0640008 0.005" quat="0.707388 -0.706825 0 0" type="box"/>
      <geom pos="-0.049 0 0.1255" quat="1 0 0 0" type="mesh" rgba="0.3 0.3 0.3 1" mesh="lds"/>
      <geom size="0.0075 0.015 0.0135" pos="0.078 0 0.107" type="box"/>

      <body name="robot_33_wheel_left" pos="0 0.144 0.033" quat="0.707388 -0.706825 0 0">
        <inertial pos="0 0 0" quat="-0.000890159 0.706886 0.000889646 0.707326" mass="0.0284989" diaginertia="2.07126e-05 1.11924e-05 1.11756e-05"/>
        <joint name="robot_33_wheel_left_joint" pos="0 0 0" axis="0 0 1" limited="false" armature="0.01"/>
        <geom quat="0.707388 0.706825 0 0" type="mesh" rgba="0.3 0.3 0.3 1" mesh="left_tire"/>
      </body>

      <body name="robot_33_wheel_right" pos="0 -0.144 0.033" quat="0.707388 -0.706825 0 0">
        <inertial pos="0 0 0" quat="-0.000890159 0.706886 0.000889646 0.707326" mass="0.0284989" diaginertia="2.07126e-05 1.11924e-05 1.11756e-05"/>
        <joint name="robot_33_wheel_right_joint" pos="0 0 0" axis="0 0 1" limited="false" armature="0.01"/>
        <geom quat="0.707388 0.706825 0 0" type="mesh" rgba="0.3 0.3 0.3 1" mesh="right_tire"/>
      </body>
    </body>

    <!-- Robot 34 -->
    <body name="robot_34_base" pos="-0.55 0.7999999999999994 0.033" euler="0 0 0.0">
      <freejoint name="robot_34_joint"/>
      <geom pos="-0.064 0 0.01" quat="1 0 0 0" type="mesh" rgba="0.4 0.4 0.4 1" mesh="waffle_pi_base"/>
      <geom size="0.015 0.0045 0.01" pos="-0.177 -0.0639992 0.005" quat="0.707388 -0.706825 0 0" type="box"/>
      <geom size="0.015 0.0045 0.01" pos="-0.177 0.0640008 0.005" quat="0.707388 -0.706825 0 0" type="box"/>
      <geom pos="-0.049 0 0.1255" quat="1 0 0 0" type="mesh" rgba="0.3 0.3 0.3 1" mesh="lds"/>
      <geom size="0.0075 0.015 0.0135" pos="0.078 0 0.107" type="box"/>

      <body name="robot_34_wheel_left" pos="0 0.144 0.033" quat="0.707388 -0.706825 0 0">
        <inertial pos="0 0 0" quat="-0.000890159 0.706886 0.000889646 0.707326" mass="0.0284989" diaginertia="2.07126e-05 1.11924e-05 1.11756e-05"/>
        <joint name="robot_34_wheel_left_joint" pos="0 0 0" axis="0 0 1" limited="false" armature="0.01"/>
        <geom quat="0.707388 0.706825 0 0" type="mesh" rgba="0.3 0.3 0.3 1" mesh="left_tire"/>
      </body>

      <body name="robot_34_wheel_right" pos="0 -0.144 0.033" quat="0.707388 -0.706825 0 0">
        <inertial pos="0 0 0" quat="-0.000890159 0.706886 0.000889646 0.707326" mass="0.0284989" diaginertia="2.07126e-05 1.11924e-05 1.11756e-05"/>
        <joint name="robot_34_wheel_right_joint" pos="0 0 0" axis="0 0 1" limited="false" armature="0.01"/>
        <geom quat="0.707388 0.706825 0 0" type="mesh" rgba="0.3 0.3 0.3 1" mesh="right_tire"/>
      </body>
    </body>

    <!-- Robot 35 -->
    <body name="robot_35_base" pos="-0.55 1.1200000000000006 0.033" euler="0 0 0.0">
      <freejoint name="robot_35_joint"/>
      <geom pos="-0.064 0 0.01" quat="1 0 0 0" type="mesh" rgba="0.4 0.4 0.4 1" mesh="waffle_pi_base"/>
      <geom size="0.015 0.0045 0.01" pos="-0.177 -0.0639992 0.005" quat="0.707388 -0.706825 0 0" type="box"/>
      <geom size="0.015 0.0045 0.01" pos="-0.177 0.0640008 0.005" quat="0.707388 -0.706825 0 0" type="box"/>
      <geom pos="-0.049 0 0.1255" quat="1 0 0 0" type="mesh" rgba="0.3 0.3 0.3 1" mesh="lds"/>
      <geom size="0.0075 0.015 0.0135" pos="0.078 0 0.107" type="box"/>

      <body name="robot_35_wheel_left" pos="0 0.144 0.033" quat="0.707388 -0.706825 0 0">
        <inertial pos="0 0 0" quat="-0.000890159 0.706886 0.000889646 0.707326" mass="0.0284989" diaginertia="2.07126e-05 1.11924e-05 1.11756e-05"/>
        <joint name="robot_35_wheel_left_joint" pos="0 0 0" axis="0 0 1" limited="false" armature="0.01"/>
        <geom quat="0.707388 0.706825 0 0" type="mesh" rgba="0.3 0.3 0.3 1" mesh="left_tire"/>
      </body>

      <body name="robot_35_wheel_right" pos="0 -0.144 0.033" quat="0.707388 -0.706825 0 0">
        <inertial pos="0 0 0" quat="-0.000890159 0.706886 0.000889646 0.707326" mass="0.0284989" diaginertia="2.07126e-05 1.11924e-05 1.11756e-05"/>
        <joint name="robot_35_wheel_right_joint" pos="0 0 0" axis="0 0 1" limited="false" armature="0.01"/>
        <geom quat="0.707388 0.706825 0 0" type="mesh" rgba="0.3 0.3 0.3 1" mesh="right_tire"/>
      </body>
    </body>

    <!-- Robot 36 -->
    <body name="robot_36_base" pos="-0.55 1.4399999999999993 0.033" euler="0 0 0.0">
      <freejoint name="robot_36_joint"/>
      <geom pos="-0.064 0 0.01" quat="1 0 0 0" type="mesh" rgba="0.4 0.4 0.4 1" mesh="waffle_pi_base"/>
      <geom size="0.015 0.0045 0.01" pos="-0.177 -0.0639992 0.005" quat="0.707388 -0.706825 0 0" type="box"/>
      <geom size="0.015 0.0045 0.01" pos="-0.177 0.0640008 0.005" quat="0.707388 -0.706825 0 0" type="box"/>
      <geom pos="-0.049 0 0.1255" quat="1 0 0 0" type="mesh" rgba="0.3 0.3 0.3 1" mesh="lds"/>
      <geom size="0.0075 0.015 0.0135" pos="0.078 0 0.107" type="box"/>

      <body name="robot_36_wheel_left" pos="0 0.144 0.033" quat="0.707388 -0.706825 0 0">
        <inertial pos="0 0 0" quat="-0.000890159 0.706886 0.000889646 0.707326" mass="0.0284989" diaginertia="2.07126e-05 1.11924e-05 1.11756e-05"/>
        <joint name="robot_36_wheel_left_joint" pos="0 0 0" axis="0 0 1" limited="false" armature="0.01"/>
        <geom quat="0.707388 0.706825 0 0" type="mesh" rgba="0.3 0.3 0.3 1" mesh="left_tire"/>
      </body>

      <body name="robot_36_wheel_right" pos="0 -0.144 0.033" quat="0.707388 -0.706825 0 0">
        <inertial pos="0 0 0" quat="-0.000890159 0.706886 0.000889646 0.707326" mass="0.0284989" diaginertia="2.07126e-05 1.11924e-05 1.11756e-05"/>
        <joint name="robot_36_wheel_right_joint" pos="0 0 0" axis="0 0 1" limited="false" armature="0.01"/>
        <geom quat="0.707388 0.706825 0 0" type="mesh" rgba="0.3 0.3 0.3 1" mesh="right_tire"/>
      </body>
    </body>

    <!-- Robot 37 -->
    <body name="robot_37_base" pos="-0.55 1.7600000000000005 0.033" euler="0 0 0.0">
      <freejoint name="robot_37_joint"/>
      <geom pos="-0.064 0 0.01" quat="1 0 0 0" type="mesh" rgba="0.4 0.4 0.4 1" mesh="waffle_pi_base"/>
      <geom size="0.015 0.0045 0.01" pos="-0.177 -0.0639992 0.005" quat="0.707388 -0.706825 0 0" type="box"/>
      <geom size="0.015 0.0045 0.01" pos="-0.177 0.0640008 0.005" quat="0.707388 -0.706825 0 0" type="box"/>
      <geom pos="-0.049 0 0.1255" quat="1 0 0 0" type="mesh" rgba="0.3 0.3 0.3 1" mesh="lds"/>
      <geom size="0.0075 0.015 0.0135" pos="0.078 0 0.107" type="box"/>

      <body name="robot_37_wheel_left" pos="0 0.144 0.033" quat="0.707388 -0.706825 0 0">
        <inertial pos="0 0 0" quat="-0.000890159 0.706886 0.000889646 0.707326" mass="0.0284989" diaginertia="2.07126e-05 1.11924e-05 1.11756e-05"/>
        <joint name="robot_37_wheel_left_joint" pos="0 0 0" axis="0 0 1" limited="false" armature="0.01"/>
        <geom quat="0.707388 0.706825 0 0" type="mesh" rgba="0.3 0.3 0.3 1" mesh="left_tire"/>
      </body>

      <body name="robot_37_wheel_right" pos="0 -0.144 0.033" quat="0.707388 -0.706825 0 0">
        <inertial pos="0 0 0" quat="-0.000890159 0.706886 0.000889646 0.707326" mass="0.0284989" diaginertia="2.07126e-05 1.11924e-05 1.11756e-05"/>
        <joint name="robot_37_wheel_right_joint" pos="0 0 0" axis="0 0 1" limited="false" armature="0.01"/>
        <geom quat="0.707388 0.706825 0 0" type="mesh" rgba="0.3 0.3 0.3 1" mesh="right_tire"/>
      </body>
    </body>

    <!-- Robot 38 -->
    <body name="robot_38_base" pos="-0.55 2.079999999999999 0.033" euler="0 0 0.0">
      <freejoint name="robot_38_joint"/>
      <geom pos="-0.064 0 0.01" quat="1 0 0 0" type="mesh" rgba="0.4 0.4 0.4 1" mesh="waffle_pi_base"/>
      <geom size="0.015 0.0045 0.01" pos="-0.177 -0.0639992 0.005" quat="0.707388 -0.706825 0 0" type="box"/>
      <geom size="0.015 0.0045 0.01" pos="-0.177 0.0640008 0.005" quat="0.707388 -0.706825 0 0" type="box"/>
      <geom pos="-0.049 0 0.1255" quat="1 0 0 0" type="mesh" rgba="0.3 0.3 0.3 1" mesh="lds"/>
      <geom size="0.0075 0.015 0.0135" pos="0.078 0 0.107" type="box"/>

      <body name="robot_38_wheel_left" pos="0 0.144 0.033" quat="0.707388 -0.706825 0 0">
        <inertial pos="0 0 0" quat="-0.000890159 0.706886 0.000889646 0.707326" mass="0.0284989" diaginertia="2.07126e-05 1.11924e-05 1.11756e-05"/>
        <joint name="robot_38_wheel_left_joint" pos="0 0 0" axis="0 0 1" limited="false" armature="0.01"/>
        <geom quat="0.707388 0.706825 0 0" type="mesh" rgba="0.3 0.3 0.3 1" mesh="left_tire"/>
      </body>

      <body name="robot_38_wheel_right" pos="0 -0.144 0.033" quat="0.707388 -0.706825 0 0">
        <inertial pos="0 0 0" quat="-0.000890159 0.706886 0.000889646 0.707326" mass="0.0284989" diaginertia="2.07126e-05 1.11924e-05 1.11756e-05"/>
        <joint name="robot_38_wheel_right_joint" pos="0 0 0" axis="0 0 1" limited="false" armature="0.01"/>
        <geom quat="0.707388 0.706825 0 0" type="mesh" rgba="0.3 0.3 0.3 1" mesh="right_tire"/>
      </body>
    </body>

    <!-- Robot 39 -->
    <body name="robot_39_base" pos="-0.55 2.4000000000000004 0.033" euler="0 0 0.0">
      <freejoint name="robot_39_joint"/>
      <geom pos="-0.064 0 0.01" quat="1 0 0 0" type="mesh" rgba="0.4 0.4 0.4 1" mesh="waffle_pi_base"/>
      <geom size="0.015 0.0045 0.01" pos="-0.177 -0.0639992 0.005" quat="0.707388 -0.706825 0 0" type="box"/>
      <geom size="0.015 0.0045 0.01" pos="-0.177 0.0640008 0.005" quat="0.707388 -0.706825 0 0" type="box"/>
      <geom pos="-0.049 0 0.1255" quat="1 0 0 0" type="mesh" rgba="0.3 0.3 0.3 1" mesh="lds"/>
      <geom size="0.0075 0.015 0.0135" pos="0.078 0 0.107" type="box"/>

      <body name="robot_39_wheel_left" pos="0 0.144 0.033" quat="0.707388 -0.706825 0 0">
        <inertial pos="0 0 0" quat="-0.000890159 0.706886 0.000889646 0.707326" mass="0.0284989" diaginertia="2.07126e-05 1.11924e-05 1.11756e-05"/>
        <joint name="robot_39_wheel_left_joint" pos="0 0 0" axis="0 0 1" limited="false" armature="0.01"/>
        <geom quat="0.707388 0.706825 0 0" type="mesh" rgba="0.3 0.3 0.3 1" mesh="left_tire"/>
      </body>

      <body name="robot_39_wheel_right" pos="0 -0.144 0.033" quat="0.707388 -0.706825 0 0">
        <inertial pos="0 0 0" quat="-0.000890159 0.706886 0.000889646 0.707326" mass="0.0284989" diaginertia="2.07126e-05 1.11924e-05 1.11756e-05"/>
        <joint name="robot_39_wheel_right_joint" pos="0 0 0" axis="0 0 1" limited="false" armature="0.01"/>
        <geom quat="0.707388 0.706825 0 0" type="mesh" rgba="0.3 0.3 0.3 1" mesh="right_tire"/>
      </body>
    </body>

    <!-- Robot 40 -->
    <body name="robot_40_base" pos="-0.55 2.7199999999999993 0.033" euler="0 0 0.0">
      <freejoint name="robot_40_joint"/>
      <geom pos="-0.064 0 0.01" quat="1 0 0 0" type="mesh" rgba="0.4 0.4 0.4 1" mesh="waffle_pi_base"/>
      <geom size="0.015 0.0045 0.01" pos="-0.177 -0.0639992 0.005" quat="0.707388 -0.706825 0 0" type="box"/>
      <geom size="0.015 0.0045 0.01" pos="-0.177 0.0640008 0.005" quat="0.707388 -0.706825 0 0" type="box"/>
      <geom pos="-0.049 0 0.1255" quat="1 0 0 0" type="mesh" rgba="0.3 0.3 0.3 1" mesh="lds"/>
      <geom size="0.0075 0.015 0.0135" pos="0.078 0 0.107" type="box"/>

      <body name="robot_40_wheel_left" pos="0 0.144 0.033" quat="0.707388 -0.706825 0 0">
        <inertial pos="0 0 0" quat="-0.000890159 0.706886 0.000889646 0.707326" mass="0.0284989" diaginertia="2.07126e-05 1.11924e-05 1.11756e-05"/>
        <joint name="robot_40_wheel_left_joint" pos="0 0 0" axis="0 0 1" limited="false" armature="0.01"/>
        <geom quat="0.707388 0.706825 0 0" type="mesh" rgba="0.3 0.3 0.3 1" mesh="left_tire"/>
      </body>

      <body name="robot_40_wheel_right" pos="0 -0.144 0.033" quat="0.707388 -0.706825 0 0">
        <inertial pos="0 0 0" quat="-0.000890159 0.706886 0.000889646 0.707326" mass="0.0284989" diaginertia="2.07126e-05 1.11924e-05 1.11756e-05"/>
        <joint name="robot_40_wheel_right_joint" pos="0 0 0" axis="0 0 1" limited="false" armature="0.01"/>
        <geom quat="0.707388 0.706825 0 0" type="mesh" rgba="0.3 0.3 0.3 1" mesh="right_tire"/>
      </body>
    </body>

    <!-- Robot 41 -->
    <body name="robot_41_base" pos="-0.55 3.0400000000000005 0.033" euler="0 0 0.0">
      <freejoint name="robot_41_joint"/>
      <geom pos="-0.064 0 0.01" quat="1 0 0 0" type="mesh" rgba="0.4 0.4 0.4 1" mesh="waffle_pi_base"/>
      <geom size="0.015 0.0045 0.01" pos="-0.177 -0.0639992 0.005" quat="0.707388 -0.706825 0 0" type="box"/>
      <geom size="0.015 0.0045 0.01" pos="-0.177 0.0640008 0.005" quat="0.707388 -0.706825 0 0" type="box"/>
      <geom pos="-0.049 0 0.1255" quat="1 0 0 0" type="mesh" rgba="0.3 0.3 0.3 1" mesh="lds"/>
      <geom size="0.0075 0.015 0.0135" pos="0.078 0 0.107" type="box"/>

      <body name="robot_41_wheel_left" pos="0 0.144 0.033" quat="0.707388 -0.706825 0 0">
        <inertial pos="0 0 0" quat="-0.000890159 0.706886 0.000889646 0.707326" mass="0.0284989" diaginertia="2.07126e-05 1.11924e-05 1.11756e-05"/>
        <joint name="robot_41_wheel_left_joint" pos="0 0 0" axis="0 0 1" limited="false" armature="0.01"/>
        <geom quat="0.707388 0.706825 0 0" type="mesh" rgba="0.3 0.3 0.3 1" mesh="left_tire"/>
      </body>

      <body name="robot_41_wheel_right" pos="0 -0.144 0.033" quat="0.707388 -0.706825 0 0">
        <inertial pos="0 0 0" quat="-0.000890159 0.706886 0.000889646 0.707326" mass="0.0284989" diaginertia="2.07126e-05 1.11924e-05 1.11756e-05"/>
        <joint name="robot_41_wheel_right_joint" pos="0 0 0" axis="0 0 1" limited="false" armature="0.01"/>
        <geom quat="0.707388 0.706825 0 0" type="mesh" rgba="0.3 0.3 0.3 1" mesh="right_tire"/>
      </body>
    </body>

    <!-- Robot 42 -->
    <body name="robot_42_base" pos="-0.55 3.3599999999999994 0.033" euler="0 0 0.0">
      <freejoint name="robot_42_joint"/>
      <geom pos="-0.064 0 0.01" quat="1 0 0 0" type="mesh" rgba="0.4 0.4 0.4 1" mesh="waffle_pi_base"/>
      <geom size="0.015 0.0045 0.01" pos="-0.177 -0.0639992 0.005" quat="0.707388 -0.706825 0 0" type="box"/>
      <geom size="0.015 0.0045 0.01" pos="-0.177 0.0640008 0.005" quat="0.707388 -0.706825 0 0" type="box"/>
      <geom pos="-0.049 0 0.1255" quat="1 0 0 0" type="mesh" rgba="0.3 0.3 0.3 1" mesh="lds"/>
      <geom size="0.0075 0.015 0.0135" pos="0.078 0 0.107" type="box"/>

      <body name="robot_42_wheel_left" pos="0 0.144 0.033" quat="0.707388 -0.706825 0 0">
        <inertial pos="0 0 0" quat="-0.000890159 0.706886 0.000889646 0.707326" mass="0.0284989" diaginertia="2.07126e-05 1.11924e-05 1.11756e-05"/>
        <joint name="robot_42_wheel_left_joint" pos="0 0 0" axis="0 0 1" limited="false" armature="0.01"/>
        <geom quat="0.707388 0.706825 0 0" type="mesh" rgba="0.3 0.3 0.3 1" mesh="left_tire"/>
      </body>

      <body name="robot_42_wheel_right" pos="0 -0.144 0.033" quat="0.707388 -0.706825 0 0">
        <inertial pos="0 0 0" quat="-0.000890159 0.706886 0.000889646 0.707326" mass="0.0284989" diaginertia="2.07126e-05 1.11924e-05 1.11756e-05"/>
        <joint name="robot_42_wheel_right_joint" pos="0 0 0" axis="0 0 1" limited="false" armature="0.01"/>
        <geom quat="0.707388 0.706825 0 0" type="mesh" rgba="0.3 0.3 0.3 1" mesh="right_tire"/>
      </body>
    </body>

    <!-- Robot 43 -->
    <body name="robot_43_base" pos="-0.55 3.68 0.033" euler="0 0 0.0">
      <freejoint name="robot_43_joint"/>
      <geom pos="-0.064 0 0.01" quat="1 0 0 0" type="mesh" rgba="0.4 0.4 0.4 1" mesh="waffle_pi_base"/>
      <geom size="0.015 0.0045 0.01" pos="-0.177 -0.0639992 0.005" quat="0.707388 -0.706825 0 0" type="box"/>
      <geom size="0.015 0.0045 0.01" pos="-0.177 0.0640008 0.005" quat="0.707388 -0.706825 0 0" type="box"/>
      <geom pos="-0.049 0 0.1255" quat="1 0 0 0" type="mesh" rgba="0.3 0.3 0.3 1" mesh="lds"/>
      <geom size="0.0075 0.015 0.0135" pos="0.078 0 0.107" type="box"/>

      <body name="robot_43_wheel_left" pos="0 0.144 0.033" quat="0.707388 -0.706825 0 0">
        <inertial pos="0 0 0" quat="-0.000890159 0.706886 0.000889646 0.707326" mass="0.0284989" diaginertia="2.07126e-05 1.11924e-05 1.11756e-05"/>
        <joint name="robot_43_wheel_left_joint" pos="0 0 0" axis="0 0 1" limited="false" armature="0.01"/>
        <geom quat="0.707388 0.706825 0 0" type="mesh" rgba="0.3 0.3 0.3 1" mesh="left_tire"/>
      </body>

      <body name="robot_43_wheel_right" pos="0 -0.144 0.033" quat="0.707388 -0.706825 0 0">
        <inertial pos="0 0 0" quat="-0.000890159 0.706886 0.000889646 0.707326" mass="0.0284989" diaginertia="2.07126e-05 1.11924e-05 1.11756e-05"/>
        <joint name="robot_43_wheel_right_joint" pos="0 0 0" axis="0 0 1" limited="false" armature="0.01"/>
        <geom quat="0.707388 0.706825 0 0" type="mesh" rgba="0.3 0.3 0.3 1" mesh="right_tire"/>
      </body>
    </body>

    <!-- Robot 44 -->
    <body name="robot_44_base" pos="-0.55 3.999999999999999 0.033" euler="0 0 0.0">
      <freejoint name="robot_44_joint"/>
      <geom pos="-0.064 0 0.01" quat="1 0 0 0" type="mesh" rgba="0.4 0.4 0.4 1" mesh="waffle_pi_base"/>
      <geom size="0.015 0.0045 0.01" pos="-0.177 -0.0639992 0.005" quat="0.707388 -0.706825 0 0" type="box"/>
      <geom size="0.015 0.0045 0.01" pos="-0.177 0.0640008 0.005" quat="0.707388 -0.706825 0 0" type="box"/>
      <geom pos="-0.049 0 0.1255" quat="1 0 0 0" type="mesh" rgba="0.3 0.3 0.3 1" mesh="lds"/>
      <geom size="0.0075 0.015 0.0135" pos="0.078 0 0.107" type="box"/>

      <body name="robot_44_wheel_left" pos="0 0.144 0.033" quat="0.707388 -0.706825 0 0">
        <inertial pos="0 0 0" quat="-0.000890159 0.706886 0.000889646 0.707326" mass="0.0284989" diaginertia="2.07126e-05 1.11924e-05 1.11756e-05"/>
        <joint name="robot_44_wheel_left_joint" pos="0 0 0" axis="0 0 1" limited="false" armature="0.01"/>
        <geom quat="0.707388 0.706825 0 0" type="mesh" rgba="0.3 0.3 0.3 1" mesh="left_tire"/>
      </body>

      <body name="robot_44_wheel_right" pos="0 -0.144 0.033" quat="0.707388 -0.706825 0 0">
        <inertial pos="0 0 0" quat="-0.000890159 0.706886 0.000889646 0.707326" mass="0.0284989" diaginertia="2.07126e-05 1.11924e-05 1.11756e-05"/>
        <joint name="robot_44_wheel_right_joint" pos="0 0 0" axis="0 0 1" limited="false" armature="0.01"/>
        <geom quat="0.707388 0.706825 0 0" type="mesh" rgba="0.3 0.3 0.3 1" mesh="right_tire"/>
      </body>
    </body>

    <!-- Robot 45 -->
    <body name="robot_45_base" pos="-0.55 4.32 0.033" euler="0 0 0.0">
      <freejoint name="robot_45_joint"/>
      <geom pos="-0.064 0 0.01" quat="1 0 0 0" type="mesh" rgba="0.4 0.4 0.4 1" mesh="waffle_pi_base"/>
      <geom size="0.015 0.0045 0.01" pos="-0.177 -0.0639992 0.005" quat="0.707388 -0.706825 0 0" type="box"/>
      <geom size="0.015 0.0045 0.01" pos="-0.177 0.0640008 0.005" quat="0.707388 -0.706825 0 0" type="box"/>
      <geom pos="-0.049 0 0.1255" quat="1 0 0 0" type="mesh" rgba="0.3 0.3 0.3 1" mesh="lds"/>
      <geom size="0.0075 0.015 0.0135" pos="0.078 0 0.107" type="box"/>

      <body name="robot_45_wheel_left" pos="0 0.144 0.033" quat="0.707388 -0.706825 0 0">
        <inertial pos="0 0 0" quat="-0.000890159 0.706886 0.000889646 0.707326" mass="0.0284989" diaginertia="2.07126e-05 1.11924e-05 1.11756e-05"/>
        <joint name="robot_45_wheel_left_joint" pos="0 0 0" axis="0 0 1" limited="false" armature="0.01"/>
        <geom quat="0.707388 0.706825 0 0" type="mesh" rgba="0.3 0.3 0.3 1" mesh="left_tire"/>
      </body>

      <body name="robot_45_wheel_right" pos="0 -0.144 0.033" quat="0.707388 -0.706825 0 0">
        <inertial pos="0 0 0" quat="-0.000890159 0.706886 0.000889646 0.707326" mass="0.0284989" diaginertia="2.07126e-05 1.11924e-05 1.11756e-05"/>
        <joint name="robot_45_wheel_right_joint" pos="0 0 0" axis="0 0 1" limited="false" armature="0.01"/>
        <geom quat="0.707388 0.706825 0 0" type="mesh" rgba="0.3 0.3 0.3 1" mesh="right_tire"/>
      </body>
    </body>

    <!-- Robot 46 -->
    <body name="robot_46_base" pos="-0.55 4.639999999999999 0.033" euler="0 0 0.0">
      <freejoint name="robot_46_joint"/>
      <geom pos="-0.064 0 0.01" quat="1 0 0 0" type="mesh" rgba="0.4 0.4 0.4 1" mesh="waffle_pi_base"/>
      <geom size="0.015 0.0045 0.01" pos="-0.177 -0.0639992 0.005" quat="0.707388 -0.706825 0 0" type="box"/>
      <geom size="0.015 0.0045 0.01" pos="-0.177 0.0640008 0.005" quat="0.707388 -0.706825 0 0" type="box"/>
      <geom pos="-0.049 0 0.1255" quat="1 0 0 0" type="mesh" rgba="0.3 0.3 0.3 1" mesh="lds"/>
      <geom size="0.0075 0.015 0.0135" pos="0.078 0 0.107" type="box"/>

      <body name="robot_46_wheel_left" pos="0 0.144 0.033" quat="0.707388 -0.706825 0 0">
        <inertial pos="0 0 0" quat="-0.000890159 0.706886 0.000889646 0.707326" mass="0.0284989" diaginertia="2.07126e-05 1.11924e-05 1.11756e-05"/>
        <joint name="robot_46_wheel_left_joint" pos="0 0 0" axis="0 0 1" limited="false" armature="0.01"/>
        <geom quat="0.707388 0.706825 0 0" type="mesh" rgba="0.3 0.3 0.3 1" mesh="left_tire"/>
      </body>

      <body name="robot_46_wheel_right" pos="0 -0.144 0.033" quat="0.707388 -0.706825 0 0">
        <inertial pos="0 0 0" quat="-0.000890159 0.706886 0.000889646 0.707326" mass="0.0284989" diaginertia="2.07126e-05 1.11924e-05 1.11756e-05"/>
        <joint name="robot_46_wheel_right_joint" pos="0 0 0" axis="0 0 1" limited="false" armature="0.01"/>
        <geom quat="0.707388 0.706825 0 0" type="mesh" rgba="0.3 0.3 0.3 1" mesh="right_tire"/>
      </body>
    </body>

    <!-- Robot 47 -->
    <body name="robot_47_base" pos="-0.55 4.96 0.033" euler="0 0 0.0">
      <freejoint name="robot_47_joint"/>
      <geom pos="-0.064 0 0.01" quat="1 0 0 0" type="mesh" rgba="0.4 0.4 0.4 1" mesh="waffle_pi_base"/>
      <geom size="0.015 0.0045 0.01" pos="-0.177 -0.0639992 0.005" quat="0.707388 -0.706825 0 0" type="box"/>
      <geom size="0.015 0.0045 0.01" pos="-0.177 0.0640008 0.005" quat="0.707388 -0.706825 0 0" type="box"/>
      <geom pos="-0.049 0 0.1255" quat="1 0 0 0" type="mesh" rgba="0.3 0.3 0.3 1" mesh="lds"/>
      <geom size="0.0075 0.015 0.0135" pos="0.078 0 0.107" type="box"/>

      <body name="robot_47_wheel_left" pos="0 0.144 0.033" quat="0.707388 -0.706825 0 0">
        <inertial pos="0 0 0" quat="-0.000890159 0.706886 0.000889646 0.707326" mass="0.0284989" diaginertia="2.07126e-05 1.11924e-05 1.11756e-05"/>
        <joint name="robot_47_wheel_left_joint" pos="0 0 0" axis="0 0 1" limited="false" armature="0.01"/>
        <geom quat="0.707388 0.706825 0 0" type="mesh" rgba="0.3 0.3 0.3 1" mesh="left_tire"/>
      </body>

      <body name="robot_47_wheel_right" pos="0 -0.144 0.033" quat="0.707388 -0.706825 0 0">
        <inertial pos="0 0 0" quat="-0.000890159 0.706886 0.000889646 0.707326" mass="0.0284989" diaginertia="2.07126e-05 1.11924e-05 1.11756e-05"/>
        <joint name="robot_47_wheel_right_joint" pos="0 0 0" axis="0 0 1" limited="false" armature="0.01"/>
        <geom quat="0.707388 0.706825 0 0" type="mesh" rgba="0.3 0.3 0.3 1" mesh="right_tire"/>
      </body>
    </body>

    <!-- Robot 48 -->
    <body name="robot_48_base" pos="-0.55 5.279999999999999 0.033" euler="0 0 0.0">
      <freejoint name="robot_48_joint"/>
      <geom pos="-0.064 0 0.01" quat="1 0 0 0" type="mesh" rgba="0.4 0.4 0.4 1" mesh="waffle_pi_base"/>
      <geom size="0.015 0.0045 0.01" pos="-0.177 -0.0639992 0.005" quat="0.707388 -0.706825 0 0" type="box"/>
      <geom size="0.015 0.0045 0.01" pos="-0.177 0.0640008 0.005" quat="0.707388 -0.706825 0 0" type="box"/>
      <geom pos="-0.049 0 0.1255" quat="1 0 0 0" type="mesh" rgba="0.3 0.3 0.3 1" mesh="lds"/>
      <geom size="0.0075 0.015 0.0135" pos="0.078 0 0.107" type="box"/>

      <body name="robot_48_wheel_left" pos="0 0.144 0.033" quat="0.707388 -0.706825 0 0">
        <inertial pos="0 0 0" quat="-0.000890159 0.706886 0.000889646 0.707326" mass="0.0284989" diaginertia="2.07126e-05 1.11924e-05 1.11756e-05"/>
        <joint name="robot_48_wheel_left_joint" pos="0 0 0" axis="0 0 1" limited="false" armature="0.01"/>
        <geom quat="0.707388 0.706825 0 0" type="mesh" rgba="0.3 0.3 0.3 1" mesh="left_tire"/>
      </body>

      <body name="robot_48_wheel_right" pos="0 -0.144 0.033" quat="0.707388 -0.706825 0 0">
        <inertial pos="0 0 0" quat="-0.000890159 0.706886 0.000889646 0.707326" mass="0.0284989" diaginertia="2.07126e-05 1.11924e-05 1.11756e-05"/>
        <joint name="robot_48_wheel_right_joint" pos="0 0 0" axis="0 0 1" limited="false" armature="0.01"/>
        <geom quat="0.707388 0.706825 0 0" type="mesh" rgba="0.3 0.3 0.3 1" mesh="right_tire"/>
      </body>
    </body>

    <!-- Robot 49 -->
    <body name="robot_49_base" pos="-0.55 5.6000000000000005 0.033" euler="0 0 0.0">
      <freejoint name="robot_49_joint"/>
      <geom pos="-0.064 0 0.01" quat="1 0 0 0" type="mesh" rgba="0.4 0.4 0.4 1" mesh="waffle_pi_base"/>
      <geom size="0.015 0.0045 0.01" pos="-0.177 -0.0639992 0.005" quat="0.707388 -0.706825 0 0" type="box"/>
      <geom size="0.015 0.0045 0.01" pos="-0.177 0.0640008 0.005" quat="0.707388 -0.706825 0 0" type="box"/>
      <geom pos="-0.049 0 0.1255" quat="1 0 0 0" type="mesh" rgba="0.3 0.3 0.3 1" mesh="lds"/>
      <geom size="0.0075 0.015 0.0135" pos="0.078 0 0.107" type="box"/>

      <body name="robot_49_wheel_left" pos="0 0.144 0.033" quat="0.707388 -0.706825 0 0">
        <inertial pos="0 0 0" quat="-0.000890159 0.706886 0.000889646 0.707326" mass="0.0284989" diaginertia="2.07126e-05 1.11924e-05 1.11756e-05"/>
        <joint name="robot_49_wheel_left_joint" pos="0 0 0" axis="0 0 1" limited="false" armature="0.01"/>
        <geom quat="0.707388 0.706825 0 0" type="mesh" rgba="0.3 0.3 0.3 1" mesh="left_tire"/>
      </body>

      <body name="robot_49_wheel_right" pos="0 -0.144 0.033" quat="0.707388 -0.706825 0 0">
        <inertial pos="0 0 0" quat="-0.000890159 0.706886 0.000889646 0.707326" mass="0.0284989" diaginertia="2.07126e-05 1.11924e-05 1.11756e-05"/>
        <joint name="robot_49_wheel_right_joint" pos="0 0 0" axis="0 0 1" limited="false" armature="0.01"/>
        <geom quat="0.707388 0.706825 0 0" type="mesh" rgba="0.3 0.3 0.3 1" mesh="right_tire"/>
      </body>
    </body>

    <!-- Robot 50 -->
    <body name="robot_50_base" pos="-0.55 5.919999999999999 0.033" euler="0 0 0.0">
      <freejoint name="robot_50_joint"/>
      <geom pos="-0.064 0 0.01" quat="1 0 0 0" type="mesh" rgba="0.4 0.4 0.4 1" mesh="waffle_pi_base"/>
      <geom size="0.015 0.0045 0.01" pos="-0.177 -0.0639992 0.005" quat="0.707388 -0.706825 0 0" type="box"/>
      <geom size="0.015 0.0045 0.01" pos="-0.177 0.0640008 0.005" quat="0.707388 -0.706825 0 0" type="box"/>
      <geom pos="-0.049 0 0.1255" quat="1 0 0 0" type="mesh" rgba="0.3 0.3 0.3 1" mesh="lds"/>
      <geom size="0.0075 0.015 0.0135" pos="0.078 0 0.107" type="box"/>

      <body name="robot_50_wheel_left" pos="0 0.144 0.033" quat="0.707388 -0.706825 0 0">
        <inertial pos="0 0 0" quat="-0.000890159 0.706886 0.000889646 0.707326" mass="0.0284989" diaginertia="2.07126e-05 1.11924e-05 1.11756e-05"/>
        <joint name="robot_50_wheel_left_joint" pos="0 0 0" axis="0 0 1" limited="false" armature="0.01"/>
        <geom quat="0.707388 0.706825 0 0" type="mesh" rgba="0.3 0.3 0.3 1" mesh="left_tire"/>
      </body>

      <body name="robot_50_wheel_right" pos="0 -0.144 0.033" quat="0.707388 -0.706825 0 0">
        <inertial pos="0 0 0" quat="-0.000890159 0.706886 0.000889646 0.707326" mass="0.0284989" diaginertia="2.07126e-05 1.11924e-05 1.11756e-05"/>
        <joint name="robot_50_wheel_right_joint" pos="0 0 0" axis="0 0 1" limited="false" armature="0.01"/>
        <geom quat="0.707388 0.706825 0 0" type="mesh" rgba="0.3 0.3 0.3 1" mesh="right_tire"/>
      </body>
    </body>

    <!-- Robot 51 -->
    <body name="robot_51_base" pos="-0.55 6.24 0.033" euler="0 0 0.0">
      <freejoint name="robot_51_joint"/>
      <geom pos="-0.064 0 0.01" quat="1 0 0 0" type="mesh" rgba="0.4 0.4 0.4 1" mesh="waffle_pi_base"/>
      <geom size="0.015 0.0045 0.01" pos="-0.177 -0.0639992 0.005" quat="0.707388 -0.706825 0 0" type="box"/>
      <geom size="0.015 0.0045 0.01" pos="-0.177 0.0640008 0.005" quat="0.707388 -0.706825 0 0" type="box"/>
      <geom pos="-0.049 0 0.1255" quat="1 0 0 0" type="mesh" rgba="0.3 0.3 0.3 1" mesh="lds"/>
      <geom size="0.0075 0.015 0.0135" pos="0.078 0 0.107" type="box"/>

      <body name="robot_51_wheel_left" pos="0 0.144 0.033" quat="0.707388 -0.706825 0 0">
        <inertial pos="0 0 0" quat="-0.000890159 0.706886 0.000889646 0.707326" mass="0.0284989" diaginertia="2.07126e-05 1.11924e-05 1.11756e-05"/>
        <joint name="robot_51_wheel_left_joint" pos="0 0 0" axis="0 0 1" limited="false" armature="0.01"/>
        <geom quat="0.707388 0.706825 0 0" type="mesh" rgba="0.3 0.3 0.3 1" mesh="left_tire"/>
      </body>

      <body name="robot_51_wheel_right" pos="0 -0.144 0.033" quat="0.707388 -0.706825 0 0">
        <inertial pos="0 0 0" quat="-0.000890159 0.706886 0.000889646 0.707326" mass="0.0284989" diaginertia="2.07126e-05 1.11924e-05 1.11756e-05"/>
        <joint name="robot_51_wheel_right_joint" pos="0 0 0" axis="0 0 1" limited="false" armature="0.01"/>
        <geom quat="0.707388 0.706825 0 0" type="mesh" rgba="0.3 0.3 0.3 1" mesh="right_tire"/>
      </body>
    </body>

    <!-- Robot 52 -->
    <body name="robot_52_base" pos="-0.55 6.559999999999999 0.033" euler="0 0 0.0">
      <freejoint name="robot_52_joint"/>
      <geom pos="-0.064 0 0.01" quat="1 0 0 0" type="mesh" rgba="0.4 0.4 0.4 1" mesh="waffle_pi_base"/>
      <geom size="0.015 0.0045 0.01" pos="-0.177 -0.0639992 0.005" quat="0.707388 -0.706825 0 0" type="box"/>
      <geom size="0.015 0.0045 0.01" pos="-0.177 0.0640008 0.005" quat="0.707388 -0.706825 0 0" type="box"/>
      <geom pos="-0.049 0 0.1255" quat="1 0 0 0" type="mesh" rgba="0.3 0.3 0.3 1" mesh="lds"/>
      <geom size="0.0075 0.015 0.0135" pos="0.078 0 0.107" type="box"/>

      <body name="robot_52_wheel_left" pos="0 0.144 0.033" quat="0.707388 -0.706825 0 0">
        <inertial pos="0 0 0" quat="-0.000890159 0.706886 0.000889646 0.707326" mass="0.0284989" diaginertia="2.07126e-05 1.11924e-05 1.11756e-05"/>
        <joint name="robot_52_wheel_left_joint" pos="0 0 0" axis="0 0 1" limited="false" armature="0.01"/>
        <geom quat="0.707388 0.706825 0 0" type="mesh" rgba="0.3 0.3 0.3 1" mesh="left_tire"/>
      </body>

      <body name="robot_52_wheel_right" pos="0 -0.144 0.033" quat="0.707388 -0.706825 0 0">
        <inertial pos="0 0 0" quat="-0.000890159 0.706886 0.000889646 0.707326" mass="0.0284989" diaginertia="2.07126e-05 1.11924e-05 1.11756e-05"/>
        <joint name="robot_52_wheel_right_joint" pos="0 0 0" axis="0 0 1" limited="false" armature="0.01"/>
        <geom quat="0.707388 0.706825 0 0" type="mesh" rgba="0.3 0.3 0.3 1" mesh="right_tire"/>
      </body>
    </body>

    <!-- Robot 53 -->
    <body name="robot_53_base" pos="-0.55 6.88 0.033" euler="0 0 0.0">
      <freejoint name="robot_53_joint"/>
      <geom pos="-0.064 0 0.01" quat="1 0 0 0" type="mesh" rgba="0.4 0.4 0.4 1" mesh="waffle_pi_base"/>
      <geom size="0.015 0.0045 0.01" pos="-0.177 -0.0639992 0.005" quat="0.707388 -0.706825 0 0" type="box"/>
      <geom size="0.015 0.0045 0.01" pos="-0.177 0.0640008 0.005" quat="0.707388 -0.706825 0 0" type="box"/>
      <geom pos="-0.049 0 0.1255" quat="1 0 0 0" type="mesh" rgba="0.3 0.3 0.3 1" mesh="lds"/>
      <geom size="0.0075 0.015 0.0135" pos="0.078 0 0.107" type="box"/>

      <body name="robot_53_wheel_left" pos="0 0.144 0.033" quat="0.707388 -0.706825 0 0">
        <inertial pos="0 0 0" quat="-0.000890159 0.706886 0.000889646 0.707326" mass="0.0284989" diaginertia="2.07126e-05 1.11924e-05 1.11756e-05"/>
        <joint name="robot_53_wheel_left_joint" pos="0 0 0" axis="0 0 1" limited="false" armature="0.01"/>
        <geom quat="0.707388 0.706825 0 0" type="mesh" rgba="0.3 0.3 0.3 1" mesh="left_tire"/>
      </body>

      <body name="robot_53_wheel_right" pos="0 -0.144 0.033" quat="0.707388 -0.706825 0 0">
        <inertial pos="0 0 0" quat="-0.000890159 0.706886 0.000889646 0.707326" mass="0.0284989" diaginertia="2.07126e-05 1.11924e-05 1.11756e-05"/>
        <joint name="robot_53_wheel_right_joint" pos="0 0 0" axis="0 0 1" limited="false" armature="0.01"/>
        <geom quat="0.707388 0.706825 0 0" type="mesh" rgba="0.3 0.3 0.3 1" mesh="right_tire"/>
      </body>
    </body>

    <!-- Robot 54 -->
    <body name="robot_54_base" pos="-0.55 7.199999999999999 0.033" euler="0 0 0.0">
      <freejoint name="robot_54_joint"/>
      <geom pos="-0.064 0 0.01" quat="1 0 0 0" type="mesh" rgba="0.4 0.4 0.4 1" mesh="waffle_pi_base"/>
      <geom size="0.015 0.0045 0.01" pos="-0.177 -0.0639992 0.005" quat="0.707388 -0.706825 0 0" type="box"/>
      <geom size="0.015 0.0045 0.01" pos="-0.177 0.0640008 0.005" quat="0.707388 -0.706825 0 0" type="box"/>
      <geom pos="-0.049 0 0.1255" quat="1 0 0 0" type="mesh" rgba="0.3 0.3 0.3 1" mesh="lds"/>
      <geom size="0.0075 0.015 0.0135" pos="0.078 0 0.107" type="box"/>

      <body name="robot_54_wheel_left" pos="0 0.144 0.033" quat="0.707388 -0.706825 0 0">
        <inertial pos="0 0 0" quat="-0.000890159 0.706886 0.000889646 0.707326" mass="0.0284989" diaginertia="2.07126e-05 1.11924e-05 1.11756e-05"/>
        <joint name="robot_54_wheel_left_joint" pos="0 0 0" axis="0 0 1" limited="false" armature="0.01"/>
        <geom quat="0.707388 0.706825 0 0" type="mesh" rgba="0.3 0.3 0.3 1" mesh="left_tire"/>
      </body>

      <body name="robot_54_wheel_right" pos="0 -0.144 0.033" quat="0.707388 -0.706825 0 0">
        <inertial pos="0 0 0" quat="-0.000890159 0.706886 0.000889646 0.707326" mass="0.0284989" diaginertia="2.07126e-05 1.11924e-05 1.11756e-05"/>
        <joint name="robot_54_wheel_right_joint" pos="0 0 0" axis="0 0 1" limited="false" armature="0.01"/>
        <geom quat="0.707388 0.706825 0 0" type="mesh" rgba="0.3 0.3 0.3 1" mesh="right_tire"/>
      </body>
    </body>

    <!-- Robot 55 -->
    <body name="robot_55_base" pos="-0.55 7.5200000000000005 0.033" euler="0 0 0.0">
      <freejoint name="robot_55_joint"/>
      <geom pos="-0.064 0 0.01" quat="1 0 0 0" type="mesh" rgba="0.4 0.4 0.4 1" mesh="waffle_pi_base"/>
      <geom size="0.015 0.0045 0.01" pos="-0.177 -0.0639992 0.005" quat="0.707388 -0.706825 0 0" type="box"/>
      <geom size="0.015 0.0045 0.01" pos="-0.177 0.0640008 0.005" quat="0.707388 -0.706825 0 0" type="box"/>
      <geom pos="-0.049 0 0.1255" quat="1 0 0 0" type="mesh" rgba="0.3 0.3 0.3 1" mesh="lds"/>
      <geom size="0.0075 0.015 0.0135" pos="0.078 0 0.107" type="box"/>

      <body name="robot_55_wheel_left" pos="0 0.144 0.033" quat="0.707388 -0.706825 0 0">
        <inertial pos="0 0 0" quat="-0.000890159 0.706886 0.000889646 0.707326" mass="0.0284989" diaginertia="2.07126e-05 1.11924e-05 1.11756e-05"/>
        <joint name="robot_55_wheel_left_joint" pos="0 0 0" axis="0 0 1" limited="false" armature="0.01"/>
        <geom quat="0.707388 0.706825 0 0" type="mesh" rgba="0.3 0.3 0.3 1" mesh="left_tire"/>
      </body>

      <body name="robot_55_wheel_right" pos="0 -0.144 0.033" quat="0.707388 -0.706825 0 0">
        <inertial pos="0 0 0" quat="-0.000890159 0.706886 0.000889646 0.707326" mass="0.0284989" diaginertia="2.07126e-05 1.11924e-05 1.11756e-05"/>
        <joint name="robot_55_wheel_right_joint" pos="0 0 0" axis="0 0 1" limited="false" armature="0.01"/>
        <geom quat="0.707388 0.706825 0 0" type="mesh" rgba="0.3 0.3 0.3 1" mesh="right_tire"/>
      </body>
    </body>

    <!-- Robot 56 -->
    <body name="robot_56_base" pos="-0.55 7.839999999999999 0.033" euler="0 0 0.0">
      <freejoint name="robot_56_joint"/>
      <geom pos="-0.064 0 0.01" quat="1 0 0 0" type="mesh" rgba="0.4 0.4 0.4 1" mesh="waffle_pi_base"/>
      <geom size="0.015 0.0045 0.01" pos="-0.177 -0.0639992 0.005" quat="0.707388 -0.706825 0 0" type="box"/>
      <geom size="0.015 0.0045 0.01" pos="-0.177 0.0640008 0.005" quat="0.707388 -0.706825 0 0" type="box"/>
      <geom pos="-0.049 0 0.1255" quat="1 0 0 0" type="mesh" rgba="0.3 0.3 0.3 1" mesh="lds"/>
      <geom size="0.0075 0.015 0.0135" pos="0.078 0 0.107" type="box"/>

      <body name="robot_56_wheel_left" pos="0 0.144 0.033" quat="0.707388 -0.706825 0 0">
        <inertial pos="0 0 0" quat="-0.000890159 0.706886 0.000889646 0.707326" mass="0.0284989" diaginertia="2.07126e-05 1.11924e-05 1.11756e-05"/>
        <joint name="robot_56_wheel_left_joint" pos="0 0 0" axis="0 0 1" limited="false" armature="0.01"/>
        <geom quat="0.707388 0.706825 0 0" type="mesh" rgba="0.3 0.3 0.3 1" mesh="left_tire"/>
      </body>

      <body name="robot_56_wheel_right" pos="0 -0.144 0.033" quat="0.707388 -0.706825 0 0">
        <inertial pos="0 0 0" quat="-0.000890159 0.706886 0.000889646 0.707326" mass="0.0284989" diaginertia="2.07126e-05 1.11924e-05 1.11756e-05"/>
        <joint name="robot_56_wheel_right_joint" pos="0 0 0" axis="0 0 1" limited="false" armature="0.01"/>
        <geom quat="0.707388 0.706825 0 0" type="mesh" rgba="0.3 0.3 0.3 1" mesh="right_tire"/>
      </body>
    </body>

    <!-- Robot 57 -->
    <body name="robot_57_base" pos="-0.55 8.16 0.033" euler="0 0 0.0">
      <freejoint name="robot_57_joint"/>
      <geom pos="-0.064 0 0.01" quat="1 0 0 0" type="mesh" rgba="0.4 0.4 0.4 1" mesh="waffle_pi_base"/>
      <geom size="0.015 0.0045 0.01" pos="-0.177 -0.0639992 0.005" quat="0.707388 -0.706825 0 0" type="box"/>
      <geom size="0.015 0.0045 0.01" pos="-0.177 0.0640008 0.005" quat="0.707388 -0.706825 0 0" type="box"/>
      <geom pos="-0.049 0 0.1255" quat="1 0 0 0" type="mesh" rgba="0.3 0.3 0.3 1" mesh="lds"/>
      <geom size="0.0075 0.015 0.0135" pos="0.078 0 0.107" type="box"/>

      <body name="robot_57_wheel_left" pos="0 0.144 0.033" quat="0.707388 -0.706825 0 0">
        <inertial pos="0 0 0" quat="-0.000890159 0.706886 0.000889646 0.707326" mass="0.0284989" diaginertia="2.07126e-05 1.11924e-05 1.11756e-05"/>
        <joint name="robot_57_wheel_left_joint" pos="0 0 0" axis="0 0 1" limited="false" armature="0.01"/>
        <geom quat="0.707388 0.706825 0 0" type="mesh" rgba="0.3 0.3 0.3 1" mesh="left_tire"/>
      </body>

      <body name="robot_57_wheel_right" pos="0 -0.144 0.033" quat="0.707388 -0.706825 0 0">
        <inertial pos="0 0 0" quat="-0.000890159 0.706886 0.000889646 0.707326" mass="0.0284989" diaginertia="2.07126e-05 1.11924e-05 1.11756e-05"/>
        <joint name="robot_57_wheel_right_joint" pos="0 0 0" axis="0 0 1" limited="false" armature="0.01"/>
        <geom quat="0.707388 0.706825 0 0" type="mesh" rgba="0.3 0.3 0.3 1" mesh="right_tire"/>
      </body>
    </body>

    <!-- Robot 58 -->
    <body name="robot_58_base" pos="-0.55 8.479999999999999 0.033" euler="0 0 0.0">
      <freejoint name="robot_58_joint"/>
      <geom pos="-0.064 0 0.01" quat="1 0 0 0" type="mesh" rgba="0.4 0.4 0.4 1" mesh="waffle_pi_base"/>
      <geom size="0.015 0.0045 0.01" pos="-0.177 -0.0639992 0.005" quat="0.707388 -0.706825 0 0" type="box"/>
      <geom size="0.015 0.0045 0.01" pos="-0.177 0.0640008 0.005" quat="0.707388 -0.706825 0 0" type="box"/>
      <geom pos="-0.049 0 0.1255" quat="1 0 0 0" type="mesh" rgba="0.3 0.3 0.3 1" mesh="lds"/>
      <geom size="0.0075 0.015 0.0135" pos="0.078 0 0.107" type="box"/>

      <body name="robot_58_wheel_left" pos="0 0.144 0.033" quat="0.707388 -0.706825 0 0">
        <inertial pos="0 0 0" quat="-0.000890159 0.706886 0.000889646 0.707326" mass="0.0284989" diaginertia="2.07126e-05 1.11924e-05 1.11756e-05"/>
        <joint name="robot_58_wheel_left_joint" pos="0 0 0" axis="0 0 1" limited="false" armature="0.01"/>
        <geom quat="0.707388 0.706825 0 0" type="mesh" rgba="0.3 0.3 0.3 1" mesh="left_tire"/>
      </body>

      <body name="robot_58_wheel_right" pos="0 -0.144 0.033" quat="0.707388 -0.706825 0 0">
        <inertial pos="0 0 0" quat="-0.000890159 0.706886 0.000889646 0.707326" mass="0.0284989" diaginertia="2.07126e-05 1.11924e-05 1.11756e-05"/>
        <joint name="robot_58_wheel_right_joint" pos="0 0 0" axis="0 0 1" limited="false" armature="0.01"/>
        <geom quat="0.707388 0.706825 0 0" type="mesh" rgba="0.3 0.3 0.3 1" mesh="right_tire"/>
      </body>
    </body>

    <!-- Robot 59 -->
    <body name="robot_59_base" pos="-0.55 8.8 0.033" euler="0 0 0.0">
      <freejoint name="robot_59_joint"/>
      <geom pos="-0.064 0 0.01" quat="1 0 0 0" type="mesh" rgba="0.4 0.4 0.4 1" mesh="waffle_pi_base"/>
      <geom size="0.015 0.0045 0.01" pos="-0.177 -0.0639992 0.005" quat="0.707388 -0.706825 0 0" type="box"/>
      <geom size="0.015 0.0045 0.01" pos="-0.177 0.0640008 0.005" quat="0.707388 -0.706825 0 0" type="box"/>
      <geom pos="-0.049 0 0.1255" quat="1 0 0 0" type="mesh" rgba="0.3 0.3 0.3 1" mesh="lds"/>
      <geom size="0.0075 0.015 0.0135" pos="0.078 0 0.107" type="box"/>

      <body name="robot_59_wheel_left" pos="0 0.144 0.033" quat="0.707388 -0.706825 0 0">
        <inertial pos="0 0 0" quat="-0.000890159 0.706886 0.000889646 0.707326" mass="0.0284989" diaginertia="2.07126e-05 1.11924e-05 1.11756e-05"/>
        <joint name="robot_59_wheel_left_joint" pos="0 0 0" axis="0 0 1" limited="false" armature="0.01"/>
        <geom quat="0.707388 0.706825 0 0" type="mesh" rgba="0.3 0.3 0.3 1" mesh="left_tire"/>
      </body>

      <body name="robot_59_wheel_right" pos="0 -0.144 0.033" quat="0.707388 -0.706825 0 0">
        <inertial pos="0 0 0" quat="-0.000890159 0.706886 0.000889646 0.707326" mass="0.0284989" diaginertia="2.07126e-05 1.11924e-05 1.11756e-05"/>
        <joint name="robot_59_wheel_right_joint" pos="0 0 0" axis="0 0 1" limited="false" armature="0.01"/>
        <geom quat="0.707388 0.706825 0 0" type="mesh" rgba="0.3 0.3 0.3 1" mesh="right_tire"/>
      </body>
    </body>

    <!-- Robot 60 -->
    <body name="robot_60_base" pos="-0.55 9.12 0.033" euler="0 0 0.0">
      <freejoint name="robot_60_joint"/>
      <geom pos="-0.064 0 0.01" quat="1 0 0 0" type="mesh" rgba="0.4 0.4 0.4 1" mesh="waffle_pi_base"/>
      <geom size="0.015 0.0045 0.01" pos="-0.177 -0.0639992 0.005" quat="0.707388 -0.706825 0 0" type="box"/>
      <geom size="0.015 0.0045 0.01" pos="-0.177 0.0640008 0.005" quat="0.707388 -0.706825 0 0" type="box"/>
      <geom pos="-0.049 0 0.1255" quat="1 0 0 0" type="mesh" rgba="0.3 0.3 0.3 1" mesh="lds"/>
      <geom size="0.0075 0.015 0.0135" pos="0.078 0 0.107" type="box"/>

      <body name="robot_60_wheel_left" pos="0 0.144 0.033" quat="0.707388 -0.706825 0 0">
        <inertial pos="0 0 0" quat="-0.000890159 0.706886 0.000889646 0.707326" mass="0.0284989" diaginertia="2.07126e-05 1.11924e-05 1.11756e-05"/>
        <joint name="robot_60_wheel_left_joint" pos="0 0 0" axis="0 0 1" limited="false" armature="0.01"/>
        <geom quat="0.707388 0.706825 0 0" type="mesh" rgba="0.3 0.3 0.3 1" mesh="left_tire"/>
      </body>

      <body name="robot_60_wheel_right" pos="0 -0.144 0.033" quat="0.707388 -0.706825 0 0">
        <inertial pos="0 0 0" quat="-0.000890159 0.706886 0.000889646 0.707326" mass="0.0284989" diaginertia="2.07126e-05 1.11924e-05 1.11756e-05"/>
        <joint name="robot_60_wheel_right_joint" pos="0 0 0" axis="0 0 1" limited="false" armature="0.01"/>
        <geom quat="0.707388 0.706825 0 0" type="mesh" rgba="0.3 0.3 0.3 1" mesh="right_tire"/>
      </body>
    </body>

    <!-- Robot 61 -->
    <body name="robot_61_base" pos="-0.55 9.44 0.033" euler="0 0 0.0">
      <freejoint name="robot_61_joint"/>
      <geom pos="-0.064 0 0.01" quat="1 0 0 0" type="mesh" rgba="0.4 0.4 0.4 1" mesh="waffle_pi_base"/>
      <geom size="0.015 0.0045 0.01" pos="-0.177 -0.0639992 0.005" quat="0.707388 -0.706825 0 0" type="box"/>
      <geom size="0.015 0.0045 0.01" pos="-0.177 0.0640008 0.005" quat="0.707388 -0.706825 0 0" type="box"/>
      <geom pos="-0.049 0 0.1255" quat="1 0 0 0" type="mesh" rgba="0.3 0.3 0.3 1" mesh="lds"/>
      <geom size="0.0075 0.015 0.0135" pos="0.078 0 0.107" type="box"/>

      <body name="robot_61_wheel_left" pos="0 0.144 0.033" quat="0.707388 -0.706825 0 0">
        <inertial pos="0 0 0" quat="-0.000890159 0.706886 0.000889646 0.707326" mass="0.0284989" diaginertia="2.07126e-05 1.11924e-05 1.11756e-05"/>
        <joint name="robot_61_wheel_left_joint" pos="0 0 0" axis="0 0 1" limited="false" armature="0.01"/>
        <geom quat="0.707388 0.706825 0 0" type="mesh" rgba="0.3 0.3 0.3 1" mesh="left_tire"/>
      </body>

      <body name="robot_61_wheel_right" pos="0 -0.144 0.033" quat="0.707388 -0.706825 0 0">
        <inertial pos="0 0 0" quat="-0.000890159 0.706886 0.000889646 0.707326" mass="0.0284989" diaginertia="2.07126e-05 1.11924e-05 1.11756e-05"/>
        <joint name="robot_61_wheel_right_joint" pos="0 0 0" axis="0 0 1" limited="false" armature="0.01"/>
        <geom quat="0.707388 0.706825 0 0" type="mesh" rgba="0.3 0.3 0.3 1" mesh="right_tire"/>
      </body>
    </body>

    <!-- Robot 62 -->
    <body name="robot_62_base" pos="-0.55 9.76 0.033" euler="0 0 0.0">
      <freejoint name="robot_62_joint"/>
      <geom pos="-0.064 0 0.01" quat="1 0 0 0" type="mesh" rgba="0.4 0.4 0.4 1" mesh="waffle_pi_base"/>
      <geom size="0.015 0.0045 0.01" pos="-0.177 -0.0639992 0.005" quat="0.707388 -0.706825 0 0" type="box"/>
      <geom size="0.015 0.0045 0.01" pos="-0.177 0.0640008 0.005" quat="0.707388 -0.706825 0 0" type="box"/>
      <geom pos="-0.049 0 0.1255" quat="1 0 0 0" type="mesh" rgba="0.3 0.3 0.3 1" mesh="lds"/>
      <geom size="0.0075 0.015 0.0135" pos="0.078 0 0.107" type="box"/>

      <body name="robot_62_wheel_left" pos="0 0.144 0.033" quat="0.707388 -0.706825 0 0">
        <inertial pos="0 0 0" quat="-0.000890159 0.706886 0.000889646 0.707326" mass="0.0284989" diaginertia="2.07126e-05 1.11924e-05 1.11756e-05"/>
        <joint name="robot_62_wheel_left_joint" pos="0 0 0" axis="0 0 1" limited="false" armature="0.01"/>
        <geom quat="0.707388 0.706825 0 0" type="mesh" rgba="0.3 0.3 0.3 1" mesh="left_tire"/>
      </body>

      <body name="robot_62_wheel_right" pos="0 -0.144 0.033" quat="0.707388 -0.706825 0 0">
        <inertial pos="0 0 0" quat="-0.000890159 0.706886 0.000889646 0.707326" mass="0.0284989" diaginertia="2.07126e-05 1.11924e-05 1.11756e-05"/>
        <joint name="robot_62_wheel_right_joint" pos="0 0 0" axis="0 0 1" limited="false" armature="0.01"/>
        <geom quat="0.707388 0.706825 0 0" type="mesh" rgba="0.3 0.3 0.3 1" mesh="right_tire"/>
      </body>
    </body>

    <!-- Robot 63 -->
    <body name="robot_63_base" pos="-0.55 10.08 0.033" euler="0 0 0.0">
      <freejoint name="robot_63_joint"/>
      <geom pos="-0.064 0 0.01" quat="1 0 0 0" type="mesh" rgba="0.4 0.4 0.4 1" mesh="waffle_pi_base"/>
      <geom size="0.015 0.0045 0.01" pos="-0.177 -0.0639992 0.005" quat="0.707388 -0.706825 0 0" type="box"/>
      <geom size="0.015 0.0045 0.01" pos="-0.177 0.0640008 0.005" quat="0.707388 -0.706825 0 0" type="box"/>
      <geom pos="-0.049 0 0.1255" quat="1 0 0 0" type="mesh" rgba="0.3 0.3 0.3 1" mesh="lds"/>
      <geom size="0.0075 0.015 0.0135" pos="0.078 0 0.107" type="box"/>

      <body name="robot_63_wheel_left" pos="0 0.144 0.033" quat="0.707388 -0.706825 0 0">
        <inertial pos="0 0 0" quat="-0.000890159 0.706886 0.000889646 0.707326" mass="0.0284989" diaginertia="2.07126e-05 1.11924e-05 1.11756e-05"/>
        <joint name="robot_63_wheel_left_joint" pos="0 0 0" axis="0 0 1" limited="false" armature="0.01"/>
        <geom quat="0.707388 0.706825 0 0" type="mesh" rgba="0.3 0.3 0.3 1" mesh="left_tire"/>
      </body>

      <body name="robot_63_wheel_right" pos="0 -0.144 0.033" quat="0.707388 -0.706825 0 0">
        <inertial pos="0 0 0" quat="-0.000890159 0.706886 0.000889646 0.707326" mass="0.0284989" diaginertia="2.07126e-05 1.11924e-05 1.11756e-05"/>
        <joint name="robot_63_wheel_right_joint" pos="0 0 0" axis="0 0 1" limited="false" armature="0.01"/>
        <geom quat="0.707388 0.706825 0 0" type="mesh" rgba="0.3 0.3 0.3 1" mesh="right_tire"/>
      </body>
    </body>

    <!-- Payload cuboid -->
    <body name="payload" pos="0.0 0.0 0.1">
      <freejoint name="payload_joint"/>
      <inertial pos="0 0 0" mass="22.400" diaginertia="0.093333 936.693333 936.637333"/>
      <geom name="payload_geom" type="box" size="0.05 11.2 0.1"
            rgba="0.8 0.4 0.2 0.9" friction="0.8 0.005 0.0001"/>
    </body>
  </worldbody>

  <!-- Actuators -->
  <actuator>

    <velocity name="robot_0_left_actuator" ctrllimited="true" ctrlrange="-30.0 30.0"
              gear="1" kv="1.0" joint="robot_0_wheel_left_joint" />
    <velocity name="robot_0_right_actuator" ctrllimited="true" ctrlrange="-30.0 30.0"
              gear="1" kv="1.0" joint="robot_0_wheel_right_joint" />

    <velocity name="robot_1_left_actuator" ctrllimited="true" ctrlrange="-30.0 30.0"
              gear="1" kv="1.0" joint="robot_1_wheel_left_joint" />
    <velocity name="robot_1_right_actuator" ctrllimited="true" ctrlrange="-30.0 30.0"
              gear="1" kv="1.0" joint="robot_1_wheel_right_joint" />

    <velocity name="robot_2_left_actuator" ctrllimited="true" ctrlrange="-30.0 30.0"
              gear="1" kv="1.0" joint="robot_2_wheel_left_joint" />
    <velocity name="robot_2_right_actuator" ctrllimited="true" ctrlrange="-30.0 30.0"
              gear="1" kv="1.0" joint="robot_2_wheel_right_joint" />

    <velocity name="robot_3_left_actuator" ctrllimited="true" ctrlrange="-30.0 30.0"
              gear="1" kv="1.0" joint="robot_3_wheel_left_joint" />
    <velocity name="robot_3_right_actuator" ctrllimited="true" ctrlrange="-30.0 30.0"
              gear="1" kv="1.0" joint="robot_3_wheel_right_joint" />

    <velocity name="robot_4_left_actuator" ctrllimited="true" ctrlrange="-30.0 30.0"
              gear="1" kv="1.0" joint="robot_4_wheel_left_joint" />
    <velocity name="robot_4_right_actuator" ctrllimited="true" ctrlrange="-30.0 30.0"
              gear="1" kv="1.0" joint="robot_4_wheel_right_joint" />

    <velocity name="robot_5_left_actuator" ctrllimited="true" ctrlrange="-30.0 30.0"
              gear="1" kv="1.0" joint="robot_5_wheel_left_joint" />
    <velocity name="robot_5_right_actuator" ctrllimited="true" ctrlrange="-30.0 30.0"
              gear="1" kv="1.0" joint="robot_5_wheel_right_joint" />

    <velocity name="robot_6_left_actuator" ctrllimited="true" ctrlrange="-30.0 30.0"
              gear="1" kv="1.0" joint="robot_6_wheel_left_joint" />
    <velocity name="robot_6_right_actuator" ctrllimited="true" ctrlrange="-30.0 30.0"
              gear="1" kv="1.0" joint="robot_6_wheel_right_joint" />

    <velocity name="robot_7_left_actuator" ctrllimited="true" ctrlrange="-30.0 30.0"
              gear="1" kv="1.0" joint="robot_7_wheel_left_joint" />
    <velocity name="robot_7_right_actuator" ctrllimited="true" ctrlrange="-30.0 30.0"
              gear="1" kv="1.0" joint="robot_7_wheel_right_joint" />

    <velocity name="robot_8_left_actuator" ctrllimited="true" ctrlrange="-30.0 30.0"
              gear="1" kv="1.0" joint="robot_8_wheel_left_joint" />
    <velocity name="robot_8_right_actuator" ctrllimited="true" ctrlrange="-30.0 30.0"
              gear="1" kv="1.0" joint="robot_8_wheel_right_joint" />

    <velocity name="robot_9_left_actuator" ctrllimited="true" ctrlrange="-30.0 30.0"
              gear="1" kv="1.0" joint="robot_9_wheel_left_joint" />
    <velocity name="robot_9_right_actuator" ctrllimited="true" ctrlrange="-30.0 30.0"
              gear="1" kv="1.0" joint="robot_9_wheel_right_joint" />

    <velocity name="robot_10_left_actuator" ctrllimited="true" ctrlrange="-30.0 30.0"
              gear="1" kv="1.0" joint="robot_10_wheel_left_joint" />
    <velocity name="robot_10_right_actuator" ctrllimited="true" ctrlrange="-30.0 30.0"
              gear="1" kv="1.0" joint="robot_10_wheel_right_joint" />

    <velocity name="robot_11_left_actuator" ctrllimited="true" ctrlrange="-30.0 30.0"
              gear="1" kv="1.0" joint="robot_11_wheel_left_joint" />
    <velocity name="robot_11_right_actuator" ctrllimited="true" ctrlrange="-30.0 30.0"
              gear="1" kv="1.0" joint="robot_11_wheel_right_joint" />

    <velocity name="robot_12_left_actuator" ctrllimited="true" ctrlrange="-30.0 30.0"
              gear="1" kv="1.0" joint="robot_12_wheel_left_joint" />
    <velocity name="robot_12_right_actuator" ctrllimited="true" ctrlrange="-30.0 30.0"
              gear="1" kv="1.0" joint="robot_12_wheel_right_joint" />

    <velocity name="robot_13_left_actuator" ctrllimited="true" ctrlrange="-30.0 30.0"
              gear="1" kv="1.0" joint="robot_13_wheel_left_joint" />
    <velocity name="robot_13_right_actuator" ctrllimited="true" ctrlrange="-30.0 30.0"
              gear="1" kv="1.0" joint="robot_13_wheel_right_joint" />

    <velocity name="robot_14_left_actuator" ctrllimited="true" ctrlrange="-30.0 30.0"
              gear="1" kv="1.0" joint="robot_14_wheel_left_joint" />
    <velocity name="robot_14_right_actuator" ctrllimited="true" ctrlrange="-30.0 30.0"
              gear="1" kv="1.0" joint="robot_14_wheel_right_joint" />

    <velocity name="robot_15_left_actuator" ctrllimited="true" ctrlrange="-30.0 30.0"
              gear="1" kv="1.0" joint="robot_15_wheel_left_joint" />
    <velocity name="robot_15_right_actuator" ctrllimited="true" ctrlrange="-30.0 30.0"
              gear="1" kv="1.0" joint="robot_15_wheel_right_joint" />

    <velocity name="robot_16_left_actuator" ctrllimited="true" ctrlrange="-30.0 30.0"
              gear="1" kv="1.0" joint="robot_16_wheel_left_joint" />
    <velocity name="robot_16_right_actuator" ctrllimited="true" ctrlrange="-30.0 30.0"
              gear="1" kv="1.0" joint="robot_16_wheel_right_joint" />

    <velocity name="robot_17_left_actuator" ctrllimited="true" ctrlrange="-30.0 30.0"
              gear="1" kv="1.0" joint="robot_17_wheel_left_joint" />
    <velocity name="robot_17_right_actuator" ctrllimited="true" ctrlrange="-30.0 30.0"
              gear="1" kv="1.0" joint="robot_17_wheel_right_joint" />

    <velocity name="robot_18_left_actuator" ctrllimited="true" ctrlrange="-30.0 30.0"
              gear="1" kv="1.0" joint="robot_18_wheel_left_joint" />
    <velocity name="robot_18_right_actuator" ctrllimited="true" ctrlrange="-30.0 30.0"
              gear="1" kv="1.0" joint="robot_18_wheel_right_joint" />

    <velocity name="robot_19_left_actuator" ctrllimited="true" ctrlrange="-30.0 30.0"
              gear="1" kv="1.0" joint="robot_19_wheel_left_joint" />
    <velocity name="robot_19_right_actuator" ctrllimited="true" ctrlrange="-30.0 30.0"
              gear="1" kv="1.0" joint="robot_19_wheel_right_joint" />

    <velocity name="robot_20_left_actuator" ctrllimited="true" ctrlrange="-30.0 30.0"
              gear="1" kv="1.0" joint="robot_20_wheel_left_joint" />
    <velocity name="robot_20_right_actuator" ctrllimited="true" ctrlrange="-30.0 30.0"
              gear="1" kv="1.0" joint="robot_20_wheel_right_joint" />

    <velocity name="robot_21_left_actuator" ctrllimited="true" ctrlrange="-30.0 30.0"
              gear="1" kv="1.0" joint="robot_21_wheel_left_joint" />
    <velocity name="robot_21_right_actuator" ctrllimited="true" ctrlrange="-30.0 30.0"
              gear="1" kv="1.0" joint="robot_21_wheel_right_joint" />

    <velocity name="robot_22_left_actuator" ctrllimited="true" ctrlrange="-30.0 30.0"
              gear="1" kv="1.0" joint="robot_22_wheel_left_joint" />
    <velocity name="robot_22_right_actuator" ctrllimited="true" ctrlrange="-30.0 30.0"
              gear="1" kv="1.0" joint="robot_22_wheel_right_joint" />

    <velocity name="robot_23_left_actuator" ctrllimited="true" ctrlrange="-30.0 30.0"
              gear="1" kv="1.0" joint="robot_23_wheel_left_joint" />
    <velocity name="robot_23_right_actuator" ctrllimited="true" ctrlrange="-30.0 30.0"
              gear="1" kv="1.0" joint="robot_23_wheel_right_joint" />

    <velocity name="robot_24_left_actuator" ctrllimited="true" ctrlrange="-30.0 30.0"
              gear="1" kv="1.0" joint="robot_24_wheel_left_joint" />
    <velocity name="robot_24_right_actuator" ctrllimited="true" ctrlrange="-30.0 30.0"
              gear="1" kv="1.0" joint="robot_24_wheel_right_joint" />

    <velocity name="robot_25_left_actuator" ctrllimited="true" ctrlrange="-30.0 30.0"
              gear="1" kv="1.0" joint="robot_25_wheel_left_joint" />
    <velocity name="robot_25_right_actuator" ctrllimited="true" ctrlrange="-30.0 30.0"
              gear="1" kv="1.0" joint="robot_25_wheel_right_joint" />

    <velocity name="robot_26_left_actuator" ctrllimited="true" ctrlrange="-30.0 30.0"
              gear="1" kv="1.0" joint="robot_26_wheel_left_joint" />
    <velocity name="robot_26_right_actuator" ctrllimited="true" ctrlrange="-30.0 30.0"
              gear="1" kv="1.0" joint="robot_26_wheel_right_joint" />

    <velocity name="robot_27_left_actuator" ctrllimited="true" ctrlrange="-30.0 30.0"
              gear="1" kv="1.0" joint="robot_27_wheel_left_joint" />
    <velocity name="robot_27_right_actuator" ctrllimited="true" ctrlrange="-30.0 30.0"
              gear="1" kv="1.0" joint="robot_27_wheel_right_joint" />

    <velocity name="robot_28_left_actuator" ctrllimited="true" ctrlrange="-30.0 30.0"
              gear="1" kv="1.0" joint="robot_28_wheel_left_joint" />
    <velocity name="robot_28_right_actuator" ctrllimited="true" ctrlrange="-30.0 30.0"
              gear="1" kv="1.0" joint="robot_28_wheel_right_joint" />

    <velocity name="robot_29_left_actuator" ctrllimited="true" ctrlrange="-30.0 30.0"
              gear="1" kv="1.0" joint="robot_29_wheel_left_joint" />
    <velocity name="robot_29_right_actuator" ctrllimited="true" ctrlrange="-30.0 30.0"
              gear="1" kv="1.0" joint="robot_29_wheel_right_joint" />

    <velocity name="robot_30_left_actuator" ctrllimited="true" ctrlrange="-30.0 30.0"
              gear="1" kv="1.0" joint="robot_30_wheel_left_joint" />
    <velocity name="robot_30_right_actuator" ctrllimited="true" ctrlrange="-30.0 30.0"
              gear="1" kv="1.0" joint="robot_30_wheel_right_joint" />

    <velocity name="robot_31_left_actuator" ctrllimited="true" ctrlrange="-30.0 30.0"
              gear="1" kv="1.0" joint="robot_31_wheel_left_joint" />
    <velocity name="robot_31_right_actuator" ctrllimited="true" ctrlrange="-30.0 30.0"
              gear="1" kv="1.0" joint="robot_31_wheel_right_joint" />

    <velocity name="robot_32_left_actuator" ctrllimited="true" ctrlrange="-30.0 30.0"
              gear="1" kv="1.0" joint="robot_32_wheel_left_joint" />
    <velocity name="robot_32_right_actuator" ctrllimited="true" ctrlrange="-30.0 30.0"
              gear="1" kv="1.0" joint="robot_32_wheel_right_joint" />

    <velocity name="robot_33_left_actuator" ctrllimited="true" ctrlrange="-30.0 30.0"
              gear="1" kv="1.0" joint="robot_33_wheel_left_joint" />
    <velocity name="robot_33_right_actuator" ctrllimited="true" ctrlrange="-30.0 30.0"
              gear="1" kv="1.0" joint="robot_33_wheel_right_joint" />

    <velocity name="robot_34_left_actuator" ctrllimited="true" ctrlrange="-30.0 30.0"
              gear="1" kv="1.0" joint="robot_34_wheel_left_joint" />
    <velocity name="robot_34_right_actuator" ctrllimited="true" ctrlrange="-30.0 30.0"
              gear="1" kv="1.0" joint="robot_34_wheel_right_joint" />

    <velocity name="robot_35_left_actuator" ctrllimited="true" ctrlrange="-30.0 30.0"
              gear="1" kv="1.0" joint="robot_35_wheel_left_joint" />
    <velocity name="robot_35_right_actuator" ctrllimited="true" ctrlrange="-30.0 30.0"
              gear="1" kv="1.0" joint="robot_35_wheel_right_joint" />

    <velocity name="robot_36_left_actuator" ctrllimited="true" ctrlrange="-30.0 30.0"
              gear="1" kv="1.0" joint="robot_36_wheel_left_joint" />
    <velocity name="robot_36_right_actuator" ctrllimited="true" ctrlrange="-30.0 30.0"
              gear="1" kv="1.0" joint="robot_36_wheel_right_joint" />

    <velocity name="robot_37_left_actuator" ctrllimited="true" ctrlrange="-30.0 30.0"
              gear="1" kv="1.0" joint="robot_37_wheel_left_joint" />
    <velocity name="robot_37_right_actuator" ctrllimited="true" ctrlrange="-30.0 30.0"
              gear="1" kv="1.0" joint="robot_37_wheel_right_joint" />

    <velocity name="robot_38_left_actuator" ctrllimited="true" ctrlrange="-30.0 30.0"
              gear="1" kv="1.0" joint="robot_38_wheel_left_joint" />
    <velocity name="robot_38_right_actuator" ctrllimited="true" ctrlrange="-30.0 30.0"
              gear="1" kv="1.0" joint="robot_38_wheel_right_joint" />

    <velocity name="robot_39_left_actuator" ctrllimited="true" ctrlrange="-30.0 30.0"
              gear="1" kv="1.0" joint="robot_39_wheel_left_joint" />
    <velocity name="robot_39_right_actuator" ctrllimited="true" ctrlrange="-30.0 30.0"
              gear="1" kv="1.0" joint="robot_39_wheel_right_joint" />

    <velocity name="robot_40_left_actuator" ctrllimited="true" ctrlrange="-30.0 30.0"
              gear="1" kv="1.0" joint="robot_40_wheel_left_joint" />
    <velocity name="robot_40_right_actuator" ctrllimited="true" ctrlrange="-30.0 30.0"
              gear="1" kv="1.0" joint="robot_40_wheel_right_joint" />

    <velocity name="robot_41_left_actuator" ctrllimited="true" ctrlrange="-30.0 30.0"
              gear="1" kv="1.0" joint="robot_41_wheel_left_joint" />
    <velocity name="robot_41_right_actuator" ctrllimited="true" ctrlrange="-30.0 30.0"
              gear="1" kv="1.0" joint="robot_41_wheel_right_joint" />

    <velocity name="robot_42_left_actuator" ctrllimited="true" ctrlrange="-30.0 30.0"
              gear="1" kv="1.0" joint="robot_42_wheel_left_joint" />
    <velocity name="robot_42_right_actuator" ctrllimited="true" ctrlrange="-30.0 30.0"
              gear="1" kv="1.0" joint="robot_42_wheel_right_joint" />

    <velocity name="robot_43_left_actuator" ctrllimited="true" ctrlrange="-30.0 30.0"
              gear="1" kv="1.0" joint="robot_43_wheel_left_joint" />
    <velocity name="robot_43_right_actuator" ctrllimited="true" ctrlrange="-30.0 30.0"
              gear="1" kv="1.0" joint="robot_43_wheel_right_joint" />

    <velocity name="robot_44_left_actuator" ctrllimited="true" ctrlrange="-30.0 30.0"
              gear="1" kv="1.0" joint="robot_44_wheel_left_joint" />
    <velocity name="robot_44_right_actuator" ctrllimited="true" ctrlrange="-30.0 30.0"
              gear="1" kv="1.0" joint="robot_44_wheel_right_joint" />

    <velocity name="robot_45_left_actuator" ctrllimited="true" ctrlrange="-30.0 30.0"
              gear="1" kv="1.0" joint="robot_45_wheel_left_joint" />
    <velocity name="robot_45_right_actuator" ctrllimited="true" ctrlrange="-30.0 30.0"
              gear="1" kv="1.0" joint="robot_45_wheel_right_joint" />

    <velocity name="robot_46_left_actuator" ctrllimited="true" ctrlrange="-30.0 30.0"
              gear="1" kv="1.0" joint="robot_46_wheel_left_joint" />
    <velocity name="robot_46_right_actuator" ctrllimited="true" ctrlrange="-30.0 30.0"
              gear="1" kv="1.0" joint="robot_46_wheel_right_joint" />

    <velocity name="robot_47_left_actuator" ctrllimited="true" ctrlrange="-30.0 30.0"
              gear="1" kv="1.0" joint="robot_47_wheel_left_joint" />
    <velocity name="robot_47_right_actuator" ctrllimited="true" ctrlrange="-30.0 30.0"
              gear="1" kv="1.0" joint="robot_47_wheel_right_joint" />

    <velocity name="robot_48_left_actuator" ctrllimited="true" ctrlrange="-30.0 30.0"
              gear="1" kv="1.0" joint="robot_48_wheel_left_joint" />
    <velocity name="robot_48_right_actuator" ctrllimited="true" ctrlrange="-30.0 30.0"
              gear="1" kv="1.0" joint="robot_48_wheel_right_joint" />

    <velocity name="robot_49_left_actuator" ctrllimited="true" ctrlrange="-30.0 30.0"
              gear="1" kv="1.0" joint="robot_49_wheel_left_joint" />
    <velocity name="robot_49_right_actuator" ctrllimited="true" ctrlrange="-30.0 30.0"
              gear="1" kv="1.0" joint="robot_49_wheel_right_joint" />

    <velocity name="robot_50_left_actuator" ctrllimited="true" ctrlrange="-30.0 30.0"
              gear="1" kv="1.0" joint="robot_50_wheel_left_joint" />
    <velocity name="robot_50_right_actuator" ctrllimited="true" ctrlrange="-30.0 30.0"
              gear="1" kv="1.0" joint="robot_50_wheel_right_joint" />

    <velocity name="robot_51_left_actuator" ctrllimited="true" ctrlrange="-30.0 30.0"
              gear="1" kv="1.0" joint="robot_51_wheel_left_joint" />
    <velocity name="robot_51_right_actuator" ctrllimited="true" ctrlrange="-30.0 30.0"
              gear="1" kv="1.0" joint="robot_51_wheel_right_joint" />

    <velocity name="robot_52_left_actuator" ctrllimited="true" ctrlrange="-30.0 30.0"
              gear="1" kv="1.0" joint="robot_52_wheel_left_joint" />
    <velocity name="robot_52_right_actuator" ctrllimited="true" ctrlrange="-30.0 30.0"
              gear="1" kv="1.0" joint="robot_52_wheel_right_joint" />

    <velocity name="robot_53_left_actuator" ctrllimited="true" ctrlrange="-30.0 30.0"
              gear="1" kv="1.0" joint="robot_53_wheel_left_joint" />
    <velocity name="robot_53_right_actuator" ctrllimited="true" ctrlrange="-30.0 30.0"
              gear="1" kv="1.0" joint="robot_53_wheel_right_joint" />

    <velocity name="robot_54_left_actuator" ctrllimited="true" ctrlrange="-30.0 30.0"
              gear="1" kv="1.0" joint="robot_54_wheel_left_joint" />
    <velocity name="robot_54_right_actuator" ctrllimited="true" ctrlrange="-30.0 30.0"
              gear="1" kv="1.0" joint="robot_54_wheel_right_joint" />

    <velocity name="robot_55_left_actuator" ctrllimited="true" ctrlrange="-30.0 30.0"
              gear="1" kv="1.0" joint="robot_55_wheel_left_joint" />
    <velocity name="robot_55_right_actuator" ctrllimited="true" ctrlrange="-30.0 30.0"
              gear="1" kv="1.0" joint="robot_55_wheel_right_joint" />

    <velocity name="robot_56_left_actuator" ctrllimited="true" ctrlrange="-30.0 30.0"
              gear="1" kv="1.0" joint="robot_56_wheel_left_joint" />
    <velocity name="robot_56_right_actuator" ctrllimited="true" ctrlrange="-30.0 30.0"
              gear="1" kv="1.0" joint="robot_56_wheel_right_joint" />

    <velocity name="robot_57_left_actuator" ctrllimited="true" ctrlrange="-30.0 30.0"
              gear="1" kv="1.0" joint="robot_57_wheel_left_joint" />
    <velocity name="robot_57_right_actuator" ctrllimited="true" ctrlrange="-30.0 30.0"
              gear="1" kv="1.0" joint="robot_57_wheel_right_joint" />

    <velocity name="robot_58_left_actuator" ctrllimited="true" ctrlrange="-30.0 30.0"
              gear="1" kv="1.0" joint="robot_58_wheel_left_joint" />
    <velocity name="robot_58_right_actuator" ctrllimited="true" ctrlrange="-30.0 30.0"
              gear="1" kv="1.0" joint="robot_58_wheel_right_joint" />

    <velocity name="robot_59_left_actuator" ctrllimited="true" ctrlrange="-30.0 30.0"
              gear="1" kv="1.0" joint="robot_59_wheel_left_joint" />
    <velocity name="robot_59_right_actuator" ctrllimited="true" ctrlrange="-30.0 30.0"
              gear="1" kv="1.0" joint="robot_59_wheel_right_joint" />

    <velocity name="robot_60_left_actuator" ctrllimited="true" ctrlrange="-30.0 30.0"
              gear="1" kv="1.0" joint="robot_60_wheel_left_joint" />
    <velocity name="robot_60_right_actuator" ctrllimited="true" ctrlrange="-30.0 30.0"
              gear="1" kv="1.0" joint="robot_60_wheel_right_joint" />

    <velocity name="robot_61_left_actuator" ctrllimited="true" ctrlrange="-30.0 30.0"
              gear="1" kv="1.0" joint="robot_61_wheel_left_joint" />
    <velocity name="robot_61_right_actuator" ctrllimited="true" ctrlrange="-30.0 30.0"
              gear="1" kv="1.0" joint="robot_61_wheel_right_joint" />

    <velocity name="robot_62_left_actuator" ctrllimited="true" ctrlrange="-30.0 30.0"
              gear="1" kv="1.0" joint="robot_62_wheel_left_joint" />
    <velocity name="robot_62_right_actuator" ctrllimited="true" ctrlrange="-30.0 30.0"
              gear="1" kv="1.0" joint="robot_62_wheel_right_joint" />

    <velocity name="robot_63_left_actuator" ctrllimited="true" ctrlrange="-30.0 30.0"
              gear="1" kv="1.0" joint="robot_63_wheel_left_joint" />
    <velocity name="robot_63_right_actuator" ctrllimited="true" ctrlrange="-30.0 30.0"
              gear="1" kv="1.0" joint="robot_63_wheel_right_joint" />
  </actuator>

  <!-- Sensors -->
  <sensor>
    <!-- Payload state sensors -->
    <framepos name="payload_pos" objtype="body" objname="payload"/>
    <framequat name="payload_quat" objtype="body" objname="payload"/>
    <framelinvel name="payload_vel" objtype="body" objname="payload"/>
  </sensor>
</mujoco>
